Workbook

Sheet Summary
B1: Data Centers
B3: Total
C4: 2026 | D4: 2027 | E4: 2028 | F4: 2029
B5: Compensation | C5: =C43+C81 -> 12484861 | D5: =D43+D81 -> 15345429 | E5: =E43+E81 -> 15345429 | F5: =F43+F81 -> 15345429
B6: Bonus | C6: =C44+C82 -> 7260350.9 | D6: =D44+D82 -> 8923863.7 | E6: =E44+E82 -> 8923863.7 | F6: =F44+F82 -> 8923863.7
B7: Essentials Bonus | C7: =C45+C83 -> 0 | D7: =D45+D83 -> 0 | E7: =E45+E83 -> 0 | F7: =F45+F83 -> 0
B8: Payroll Taxes | C8: =C46+C84 -> 1451993.8 | D8: =D46+D84 -> 1784678.8 | E8: =E46+E84 -> 1784678.8 | F8: =F46+F84 -> 1784678.8
B9: Benefits | C9: =C47+C85 -> 1484837.4 | D9: =D47+D85 -> 1825047.6 | E9: =E47+E85 -> 1825047.6 | F9: =F47+F85 -> 1825047.6
B10: Vacation | C10: =C48+C86 -> 54952.65 | D10: =D48+D86 -> 67543.562 | E10: =E48+E86 -> 67543.562 | F10: =F48+F86 -> 67543.562
B11: Other | C11: =C49+C87 -> 0 | D11: =D49+D87 -> 0 | E11: =E49+E87 -> 0 | F11: =F49+F87 -> 0
B12: Contract Labor | C12: =C50+C88 -> 0 | D12: =D50+D88 -> 0 | E12: =E50+E88 -> 0 | F12: =F50+F88 -> 0
B13: LTIP Compensation | C13: =C51+C89 -> 3562244.9 | D13: =D51+D89 -> 6332657.8 | E13: =E51+E89 -> 6332657.8 | F13: =F51+F89 -> 6332657.8
B14: Total Payroll | C14: =SUM(C5:C13) -> 26299241 | D14: =SUM(D5:D13) -> 34279221 | E14: =E52+E90 -> 34279221 | F14: =F52+F90 -> 34279221
B16: Professional Fees | C16: =C54+C92 -> 328734 | D16: =D54+D92 -> 328734 | E16: =E54+E92 -> 328734 | F16: =F54+F92 -> 328734
B17: Occupancy | C17: =C55+C93 -> -65529 | D17: =D55+D93 -> -65529 | E17: =E55+E93 -> -65529 | F17: =F55+F93 -> -65529
B18: Office Expenses | C18: =C56+C94 -> -3040.82 | D18: =D56+D94 -> -3040.82 | E18: =E56+E94 -> -3040.82 | F18: =F56+F94 -> -3040.82
B19: IT Costs | C19: =C57+C95 -> 7089.24 | D19: =D57+D95 -> 7089.24 | E19: =E57+E95 -> 7089.24 | F19: =F57+F95 -> 7089.24
B20: Marketing and Presentation | C20: =C58+C96 -> 0 | D20: =D58+D96 -> 0 | E20: =E58+E96 -> 0 | F20: =F58+F96 -> 0
B21: Travel and Entertainment | C21: =C59+C97 -> 945298.56 | D21: =D59+D97 -> 945298.56 | E21: =E59+E97 -> 945298.56 | F21: =F59+F97 -> 945298.56
B22: Employee events | C22: =C60+C98 -> 119350.72 | D22: =D60+D98 -> 119350.72 | E22: =E60+E98 -> 119350.72 | F22: =F60+F98 -> 119350.72
B23: Insurance Non Property | C23: =C61+C99 -> 0 | D23: =D61+D99 -> 0 | E23: =E61+E99 -> 0 | F23: =F61+F99 -> 0
B24: Licenses | C24: =C62+C100 -> 0 | D24: =D62+D100 -> 0 | E24: =E62+E100 -> 0 | F24: =F62+F100 -> 0
B25: Recruiting and Relocation | C25: =C63+C101 -> 959676.43 | D25: =D63+D101 -> 959676.43 | E25: =E63+E101 -> 959676.43 | F25: =F63+F101 -> 959676.43
B26: Seminars and Training | C26: =C64+C102 -> 36097.76 | D26: =D64+D102 -> 36097.76 | E26: =E64+E102 -> 36097.76 | F26: =F64+F102 -> 36097.76
B27: Shareholder Relations | C27: =C65+C103 -> 0 | D27: =D65+D103 -> 0 | E27: =E65+E103 -> 0 | F27: =F65+F103 -> 0
... B36: Allocated IT & Office Contra | C36: =C74+C112 -> 0 | D36: =D74+D112 -> 0 | E36: =E74+E112 -> 0 | F36: =F74+F112 -> 0
B37: Total Non-Payroll | C37: =SUM(C16:C36) -> 2649576.1 | D37: =SUM(D16:D36) -> 2649576.1 | E37: =E75+E113 -> 2649576.1 | F37: =F75+F113 -> 2649576.1
B39: Total | C39: =C14+C37 -> 28948817 | D39: =D14+D37 -> 36928797 | E39: =E77+E115 -> 36928797 | F39: =F77+F115 -> 36928797
B41: Baseline
C42: 2026 | D42: 2027 | E42: 2028 | F42: 2029
B43: Compensation | C43: =SUMIFS('Base - Payroll'!$E:$E,'Base - Payroll'!$A:$A,Summary!$B43) -> 12484861 | D43: =SUMIFS('Base - Payroll'!$G:$G,'Base - Payroll'!$A:$A,Summary!$B43) -> 15345429 | E43: =SUMIFS('Base - Payroll'!$H:$H,'Base - Payroll'!$A:$A,Summary!$B43) -> 15345429 | F43: =SUMIFS('Base - Payroll'!$I:$I,'Base - Payroll'!$A:$A,Summary!$B43) -> 15345429
B44: Bonus | C44: =SUMIFS('Base - Payroll'!$E:$E,'Base - Payroll'!$A:$A,Summary!$B44) -> 7260350.9 | D44: =SUMIFS('Base - Payroll'!$G:$G,'Base - Payroll'!$A:$A,Summary!$B44) -> 8923863.7 | E44: =SUMIFS('Base - Payroll'!$H:$H,'Base - Payroll'!$A:$A,Summary!$B44) -> 8923863.7 | F44: =SUMIFS('Base - Payroll'!$I:$I,'Base - Payroll'!$A:$A,Summary!$B44) -> 8923863.7
B45: Essentials Bonus | C45: =SUMIFS('Base - Non-Payroll'!$E:$E,'Base - Non-Payroll'!$A:$A,Summary!$B45) -> 0 | D45: =SUMIFS('Base - Non-Payroll'!$H:$H,'Base - Non-Payroll'!$A:$A,Summary!$B45) -> 0 | E45: =SUMIFS('Base - Non-Payroll'!$J:$J,'Base - Non-Payroll'!$A:$A,Summary!$B45) -> 0 | F45: =SUMIFS('Base - Non-Payroll'!$L:$L,'Base - Non-Payroll'!$A:$A,Summary!$B45) -> 0
B46: Payroll Taxes | C46: =SUMIFS('Base - Payroll'!$E:$E,'Base - Payroll'!$A:$A,Summary!$B46) -> 1451993.8 | D46: =SUMIFS('Base - Payroll'!$G:$G,'Base - Payroll'!$A:$A,Summary!$B46) -> 1784678.8 | E46: =SUMIFS('Base - Payroll'!$H:$H,'Base - Payroll'!$A:$A,Summary!$B46) -> 1784678.8 | F46: =SUMIFS('Base - Payroll'!$I:$I,'Base - Payroll'!$A:$A,Summary!$B46) -> 1784678.8
B47: Benefits | C47: =SUMIFS('Base - Payroll'!$E:$E,'Base - Payroll'!$A:$A,Summary!$B47) -> 1484837.4 | D47: =SUMIFS('Base - Payroll'!$G:$G,'Base - Payroll'!$A:$A,Summary!$B47) -> 1825047.6 | E47: =SUMIFS('Base - Payroll'!$H:$H,'Base - Payroll'!$A:$A,Summary!$B47) -> 1825047.6 | F47: =SUMIFS('Base - Payroll'!$I:$I,'Base - Payroll'!$A:$A,Summary!$B47) -> 1825047.6
B48: Vacation | C48: =SUMIFS('Base - Payroll'!$E:$E,'Base - Payroll'!$A:$A,Summary!$B48) -> 54952.65 | D48: =SUMIFS('Base - Payroll'!$G:$G,'Base - Payroll'!$A:$A,Summary!$B48) -> 67543.562 | E48: =SUMIFS('Base - Payroll'!$H:$H,'Base - Payroll'!$A:$A,Summary!$B48) -> 67543.562 | F48: =SUMIFS('Base - Payroll'!$I:$I,'Base - Payroll'!$A:$A,Summary!$B48) -> 67543.562
B49: Other | C49: =SUMIFS('Base - Payroll'!$E:$E,'Base - Payroll'!$A:$A,Summary!$B49) -> 0 | D49: =SUMIFS('Base - Payroll'!$G:$G,'Base - Payroll'!$A:$A,Summary!$B49) -> 0 | E49: =SUMIFS('Base - Payroll'!$H:$H,'Base - Payroll'!$A:$A,Summary!$B49) -> 0 | F49: =SUMIFS('Base - Payroll'!$I:$I,'Base - Payroll'!$A:$A,Summary!$B49) -> 0
B50: Contract Labor | C50: =SUMIFS('Base - Non-Payroll'!$E:$E,'Base - Non-Payroll'!$A:$A,Summary!$B50) -> 0 | D50: =SUMIFS('Base - Non-Payroll'!$H:$H,'Base - Non-Payroll'!$A:$A,Summary!$B50) -> 0 | E50: =SUMIFS('Base - Non-Payroll'!$J:$J,'Base - Non-Payroll'!$A:$A,Summary!$B50) -> 0 | F50: =SUMIFS('Base - Non-Payroll'!$L:$L,'Base - Non-Payroll'!$A:$A,Summary!$B50) -> 0
B51: LTIP Compensation | C51: =SUMIFS('Base - Payroll'!$E:$E,'Base - Payroll'!$A:$A,Summary!$B51) -> 3562244.9 | D51: =SUMIFS('Base - Payroll'!$G:$G,'Base - Payroll'!$A:$A,Summary!$B51) -> 6332657.8 | E51: =SUMIFS('Base - Payroll'!$H:$H,'Base - Payroll'!$A:$A,Summary!$B51) -> 6332657.8 | F51: =SUMIFS('Base - Payroll'!$I:$I,'Base - Payroll'!$A:$A,Summary!$B51) -> 6332657.8
B52: Baseline Payroll | C52: =SUM(C43:C51) -> 26299241 | D52: =SUM(D43:D51) -> 34279221 | E52: =SUM(E43:E51) -> 34279221 | F52: =SUM(F43:F51) -> 34279221
...

Sheet Investment Case Asks - Summary
A1: Investment Case Asks - Incremental Spend Input
A3: Payroll / Headcount Incremental Spend | T3: Incremental Spend Summary
A4: Job Title | B4: Job Level | C4: Role / Hire | D4: Location (City/Country) | E4: Key Job Responsibilities | F4: Hire Date | G4: Base Salary | H4: Bonus % | I4: Bonus | J4: Payroll Taxes | K4: Benefits | L4: Vacation | M4: Other | N4: Annualized Spend | O4: 2027 Incremental Spend | P4: 2028 Incremental Spend | Q4: 2029 Incremental Spend | R4: Notes / Rationale | T4: Spend Type | U4: 2027 | V4: 2028 | W4: 2029
A5: =IFERROR(IF('Investment Case Asks - Monthly'!A5="","",'Investment Case Asks - Monthly'!A5),"") | B5: =IFERROR(IF('Investment Case Asks - Monthly'!B5="","",'Investment Case Asks - Monthly'!B5),"") | C5: =IFERROR(IF('Investment Case Asks - Monthly'!C5="","",'Investment Case Asks - Monthly'!C5),"") | D5: =IFERROR(IF('Investment Case Asks - Monthly'!D5="","",'Investment Case Asks - Monthly'!D5),"") | E5: =IFERROR(IF('Investment Case Asks - Monthly'!E5="","",'Investment Case Asks - Monthly'!E5),"") | F5: =IFERROR(IF('Investment Case Asks - Monthly'!F5="","",'Investment Case Asks - Monthly'!F5),"") | G5: =IFERROR(IF('Investment Case Asks - Monthly'!G5="","",'Investment Case Asks - Monthly'!G5),"") | H5: =IFERROR(IF('Investment Case Asks - Monthly'!H5="","",'Investment Case Asks - Monthly'!H5),"") | ... N5: =IFERROR(IF('Investment Case Asks - Monthly'!N5="","",'Investment Case Asks - Monthly'!N5),"") | O5: =IFERROR(IF('Investment Case Asks - Monthly'!AA5="","",'Investment Case Asks - Monthly'!AA5),"") | P5: =IFERROR(IF('Investment Case Asks - Monthly'!AN5="","",'Investment Case Asks - Monthly'!AN5),"") | Q5: =IFERROR(IF('Investment Case Asks - Monthly'!BA5="","",'Investment Case Asks - Monthly'!BA5),"") | R5: =IFERROR(IF('Investment Case Asks - Monthly'!BB5="","",'Investment Case Asks - Monthly'!BB5),"") | T5: Payroll / Headcount | U5: =O22 -> 0 | V5: =P22 -> 0 | W5: =Q22 -> 0
A6: =IFERROR(IF('Investment Case Asks - Monthly'!A6="","",'Investment Case Asks - Monthly'!A6),"") | B6: =IFERROR(IF('Investment Case Asks - Monthly'!B6="","",'Investment Case Asks - Monthly'!B6),"") | C6: =IFERROR(IF('Investment Case Asks - Monthly'!C6="","",'Investment Case Asks - Monthly'!C6),"") | D6: =IFERROR(IF('Investment Case Asks - Monthly'!D6="","",'Investment Case Asks - Monthly'!D6),"") | E6: =IFERROR(IF('Investment Case Asks - Monthly'!E6="","",'Investment Case Asks - Monthly'!E6),"") | F6: =IFERROR(IF('Investment Case Asks - Monthly'!F6="","",'Investment Case Asks - Monthly'!F6),"") | G6: =IFERROR(IF('Investment Case Asks - Monthly'!G6="","",'Investment Case Asks - Monthly'!G6),"") | H6: =IFERROR(IF('Investment Case Asks - Monthly'!H6="","",'Investment Case Asks - Monthly'!H6),"") | ... N6: =IFERROR(IF('Investment Case Asks - Monthly'!N6="","",'Investment Case Asks - Monthly'!N6),"") | O6: =IFERROR(IF('Investment Case Asks - Monthly'!AA6="","",'Investment Case Asks - Monthly'!AA6),"") | P6: =IFERROR(IF('Investment Case Asks - Monthly'!AN6="","",'Investment Case Asks - Monthly'!AN6),"") | Q6: =IFERROR(IF('Investment Case Asks - Monthly'!BA6="","",'Investment Case Asks - Monthly'!BA6),"") | R6: =IFERROR(IF('Investment Case Asks - Monthly'!BB6="","",'Investment Case Asks - Monthly'!BB6),"") | T6: Non-Payroll | U6: =D44 -> 0 | V6: =E44 -> 0 | W6: =F44 -> 0
A7: =IFERROR(IF('Investment Case Asks - Monthly'!A7="","",'Investment Case Asks - Monthly'!A7),"") | B7: =IFERROR(IF('Investment Case Asks - Monthly'!B7="","",'Investment Case Asks - Monthly'!B7),"") | C7: =IFERROR(IF('Investment Case Asks - Monthly'!C7="","",'Investment Case Asks - Monthly'!C7),"") | D7: =IFERROR(IF('Investment Case Asks - Monthly'!D7="","",'Investment Case Asks - Monthly'!D7),"") | E7: =IFERROR(IF('Investment Case Asks - Monthly'!E7="","",'Investment Case Asks - Monthly'!E7),"") | F7: =IFERROR(IF('Investment Case Asks - Monthly'!F7="","",'Investment Case Asks - Monthly'!F7),"") | G7: =IFERROR(IF('Investment Case Asks - Monthly'!G7="","",'Investment Case Asks - Monthly'!G7),"") | H7: =IFERROR(IF('Investment Case Asks - Monthly'!H7="","",'Investment Case Asks - Monthly'!H7),"") | ... N7: =IFERROR(IF('Investment Case Asks - Monthly'!N7="","",'Investment Case Asks - Monthly'!N7),"") | O7: =IFERROR(IF('Investment Case Asks - Monthly'!AA7="","",'Investment Case Asks - Monthly'!AA7),"") | P7: =IFERROR(IF('Investment Case Asks - Monthly'!AN7="","",'Investment Case Asks - Monthly'!AN7),"") | Q7: =IFERROR(IF('Investment Case Asks - Monthly'!BA7="","",'Investment Case Asks - Monthly'!BA7),"") | R7: =IFERROR(IF('Investment Case Asks - Monthly'!BB7="","",'Investment Case Asks - Monthly'!BB7),"") | T7: Total Incremental Spend | U7: =SUM(U5:U6) -> 0 | V7: =SUM(V5:V6) -> 0 | W7: =SUM(W5:W6) -> 0
A8: =IFERROR(IF('Investment Case Asks - Monthly'!A8="","",'Investment Case Asks - Monthly'!A8),"") | B8: =IFERROR(IF('Investment Case Asks - Monthly'!B8="","",'Investment Case Asks - Monthly'!B8),"") | C8: =IFERROR(IF('Investment Case Asks - Monthly'!C8="","",'Investment Case Asks - Monthly'!C8),"") | D8: =IFERROR(IF('Investment Case Asks - Monthly'!D8="","",'Investment Case Asks - Monthly'!D8),"") | E8: =IFERROR(IF('Investment Case Asks - Monthly'!E8="","",'Investment Case Asks - Monthly'!E8),"") | F8: =IFERROR(IF('Investment Case Asks - Monthly'!F8="","",'Investment Case Asks - Monthly'!F8),"") | G8: =IFERROR(IF('Investment Case Asks - Monthly'!G8="","",'Investment Case Asks - Monthly'!G8),"") | H8: =IFERROR(IF('Investment Case Asks - Monthly'!H8="","",'Investment Case Asks - Monthly'!H8),"") | ... N8: =IFERROR(IF('Investment Case Asks - Monthly'!N8="","",'Investment Case Asks - Monthly'!N8),"") | O8: =IFERROR(IF('Investment Case Asks - Monthly'!AA8="","",'Investment Case Asks - Monthly'!AA8),"") | P8: =IFERROR(IF('Investment Case Asks - Monthly'!AN8="","",'Investment Case Asks - Monthly'!AN8),"") | Q8: =IFERROR(IF('Investment Case Asks - Monthly'!BA8="","",'Investment Case Asks - Monthly'!BA8),"") | R8: =IFERROR(IF('Investment Case Asks - Monthly'!BB8="","",'Investment Case Asks - Monthly'!BB8),"")
A9: =IFERROR(IF('Investment Case Asks - Monthly'!A9="","",'Investment Case Asks - Monthly'!A9),"") | B9: =IFERROR(IF('Investment Case Asks - Monthly'!B9="","",'Investment Case Asks - Monthly'!B9),"") | C9: =IFERROR(IF('Investment Case Asks - Monthly'!C9="","",'Investment Case Asks - Monthly'!C9),"") | D9: =IFERROR(IF('Investment Case Asks - Monthly'!D9="","",'Investment Case Asks - Monthly'!D9),"") | E9: =IFERROR(IF('Investment Case Asks - Monthly'!E9="","",'Investment Case Asks - Monthly'!E9),"") | F9: =IFERROR(IF('Investment Case Asks - Monthly'!F9="","",'Investment Case Asks - Monthly'!F9),"") | G9: =IFERROR(IF('Investment Case Asks - Monthly'!G9="","",'Investment Case Asks - Monthly'!G9),"") | H9: =IFERROR(IF('Investment Case Asks - Monthly'!H9="","",'Investment Case Asks - Monthly'!H9),"") | ... N9: =IFERROR(IF('Investment Case Asks - Monthly'!N9="","",'Investment Case Asks - Monthly'!N9),"") | O9: =IFERROR(IF('Investment Case Asks - Monthly'!AA9="","",'Investment Case Asks - Monthly'!AA9),"") | P9: =IFERROR(IF('Investment Case Asks - Monthly'!AN9="","",'Investment Case Asks - Monthly'!AN9),"") | Q9: =IFERROR(IF('Investment Case Asks - Monthly'!BA9="","",'Investment Case Asks - Monthly'!BA9),"") | R9: =IFERROR(IF('Investment Case Asks - Monthly'!BB9="","",'Investment Case Asks - Monthly'!BB9),"")
A10: =IFERROR(IF('Investment Case Asks - Monthly'!A10="","",'Investment Case Asks - Monthly'!A10),"") | B10: =IFERROR(IF('Investment Case Asks - Monthly'!B10="","",'Investment Case Asks - Monthly'!B10),"") | C10: =IFERROR(IF('Investment Case Asks - Monthly'!C10="","",'Investment Case Asks - Monthly'!C10),"") | D10: =IFERROR(IF('Investment Case Asks - Monthly'!D10="","",'Investment Case Asks - Monthly'!D10),"") | E10: =IFERROR(IF('Investment Case Asks - Monthly'!E10="","",'Investment Case Asks - Monthly'!E10),"") | F10: =IFERROR(IF('Investment Case Asks - Monthly'!F10="","",'Investment Case Asks - Monthly'!F10),"") | G10: =IFERROR(IF('Investment Case Asks - Monthly'!G10="","",'Investment Case Asks - Monthly'!G10),"") | H10: =IFERROR(IF('Investment Case Asks - Monthly'!H10="","",'Investment Case Asks - Monthly'!H10),"") | ... N10: =IFERROR(IF('Investment Case Asks - Monthly'!N10="","",'Investment Case Asks - Monthly'!N10),"") | O10: =IFERROR(IF('Investment Case Asks - Monthly'!AA10="","",'Investment Case Asks - Monthly'!AA10),"") | P10: =IFERROR(IF('Investment Case Asks - Monthly'!AN10="","",'Investment Case Asks - Monthly'!AN10),"") | Q10: =IFERROR(IF('Investment Case Asks - Monthly'!BA10="","",'Investment Case Asks - Monthly'!BA10),"") | R10: =IFERROR(IF('Investment Case Asks - Monthly'!BB10="","",'Investment Case Asks - Monthly'!BB10),"")
A11: =IFERROR(IF('Investment Case Asks - Monthly'!A11="","",'Investment Case Asks - Monthly'!A11),"") | B11: =IFERROR(IF('Investment Case Asks - Monthly'!B11="","",'Investment Case Asks - Monthly'!B11),"") | C11: =IFERROR(IF('Investment Case Asks - Monthly'!C11="","",'Investment Case Asks - Monthly'!C11),"") | D11: =IFERROR(IF('Investment Case Asks - Monthly'!D11="","",'Investment Case Asks - Monthly'!D11),"") | E11: =IFERROR(IF('Investment Case Asks - Monthly'!E11="","",'Investment Case Asks - Monthly'!E11),"") | F11: =IFERROR(IF('Investment Case Asks - Monthly'!F11="","",'Investment Case Asks - Monthly'!F11),"") | G11: =IFERROR(IF('Investment Case Asks - Monthly'!G11="","",'Investment Case Asks - Monthly'!G11),"") | H11: =IFERROR(IF('Investment Case Asks - Monthly'!H11="","",'Investment Case Asks - Monthly'!H11),"") | ... N11: =IFERROR(IF('Investment Case Asks - Monthly'!N11="","",'Investment Case Asks - Monthly'!N11),"") | O11: =IFERROR(IF('Investment Case Asks - Monthly'!AA11="","",'Investment Case Asks - Monthly'!AA11),"") | P11: =IFERROR(IF('Investment Case Asks - Monthly'!AN11="","",'Investment Case Asks - Monthly'!AN11),"") | Q11: =IFERROR(IF('Investment Case Asks - Monthly'!BA11="","",'Investment Case Asks - Monthly'!BA11),"") | R11: =IFERROR(IF('Investment Case Asks - Monthly'!BB11="","",'Investment Case Asks - Monthly'!BB11),"")
A12: =IFERROR(IF('Investment Case Asks - Monthly'!A12="","",'Investment Case Asks - Monthly'!A12),"") | B12: =IFERROR(IF('Investment Case Asks - Monthly'!B12="","",'Investment Case Asks - Monthly'!B12),"") | C12: =IFERROR(IF('Investment Case Asks - Monthly'!C12="","",'Investment Case Asks - Monthly'!C12),"") | D12: =IFERROR(IF('Investment Case Asks - Monthly'!D12="","",'Investment Case Asks - Monthly'!D12),"") | E12: =IFERROR(IF('Investment Case Asks - Monthly'!E12="","",'Investment Case Asks - Monthly'!E12),"") | F12: =IFERROR(IF('Investment Case Asks - Monthly'!F12="","",'Investment Case Asks - Monthly'!F12),"") | G12: =IFERROR(IF('Investment Case Asks - Monthly'!G12="","",'Investment Case Asks - Monthly'!G12),"") | H12: =IFERROR(IF('Investment Case Asks - Monthly'!H12="","",'Investment Case Asks - Monthly'!H12),"") | ... N12: =IFERROR(IF('Investment Case Asks - Monthly'!N12="","",'Investment Case Asks - Monthly'!N12),"") | O12: =IFERROR(IF('Investment Case Asks - Monthly'!AA12="","",'Investment Case Asks - Monthly'!AA12),"") | P12: =IFERROR(IF('Investment Case Asks - Monthly'!AN12="","",'Investment Case Asks - Monthly'!AN12),"") | Q12: =IFERROR(IF('Investment Case Asks - Monthly'!BA12="","",'Investment Case Asks - Monthly'!BA12),"") | R12: =IFERROR(IF('Investment Case Asks - Monthly'!BB12="","",'Investment Case Asks - Monthly'!BB12),"")
A13: =IFERROR(IF('Investment Case Asks - Monthly'!A13="","",'Investment Case Asks - Monthly'!A13),"") | B13: =IFERROR(IF('Investment Case Asks - Monthly'!B13="","",'Investment Case Asks - Monthly'!B13),"") | C13: =IFERROR(IF('Investment Case Asks - Monthly'!C13="","",'Investment Case Asks - Monthly'!C13),"") | D13: =IFERROR(IF('Investment Case Asks - Monthly'!D13="","",'Investment Case Asks - Monthly'!D13),"") | E13: =IFERROR(IF('Investment Case Asks - Monthly'!E13="","",'Investment Case Asks - Monthly'!E13),"") | F13: =IFERROR(IF('Investment Case Asks - Monthly'!F13="","",'Investment Case Asks - Monthly'!F13),"") | G13: =IFERROR(IF('Investment Case Asks - Monthly'!G13="","",'Investment Case Asks - Monthly'!G13),"") | H13: =IFERROR(IF('Investment Case Asks - Monthly'!H13="","",'Investment Case Asks - Monthly'!H13),"") | ... N13: =IFERROR(IF('Investment Case Asks - Monthly'!N13="","",'Investment Case Asks - Monthly'!N13),"") | O13: =IFERROR(IF('Investment Case Asks - Monthly'!AA13="","",'Investment Case Asks - Monthly'!AA13),"") | P13: =IFERROR(IF('Investment Case Asks - Monthly'!AN13="","",'Investment Case Asks - Monthly'!AN13),"") | Q13: =IFERROR(IF('Investment Case Asks - Monthly'!BA13="","",'Investment Case Asks - Monthly'!BA13),"") | R13: =IFERROR(IF('Investment Case Asks - Monthly'!BB13="","",'Investment Case Asks - Monthly'!BB13),"")
A14: =IFERROR(IF('Investment Case Asks - Monthly'!A14="","",'Investment Case Asks - Monthly'!A14),"") | B14: =IFERROR(IF('Investment Case Asks - Monthly'!B14="","",'Investment Case Asks - Monthly'!B14),"") | C14: =IFERROR(IF('Investment Case Asks - Monthly'!C14="","",'Investment Case Asks - Monthly'!C14),"") | D14: =IFERROR(IF('Investment Case Asks - Monthly'!D14="","",'Investment Case Asks - Monthly'!D14),"") | E14: =IFERROR(IF('Investment Case Asks - Monthly'!E14="","",'Investment Case Asks - Monthly'!E14),"") | F14: =IFERROR(IF('Investment Case Asks - Monthly'!F14="","",'Investment Case Asks - Monthly'!F14),"") | G14: =IFERROR(IF('Investment Case Asks - Monthly'!G14="","",'Investment Case Asks - Monthly'!G14),"") | H14: =IFERROR(IF('Investment Case Asks - Monthly'!H14="","",'Investment Case Asks - Monthly'!H14),"") | ... N14: =IFERROR(IF('Investment Case Asks - Monthly'!N14="","",'Investment Case Asks - Monthly'!N14),"") | O14: =IFERROR(IF('Investment Case Asks - Monthly'!AA14="","",'Investment Case Asks - Monthly'!AA14),"") | P14: =IFERROR(IF('Investment Case Asks - Monthly'!AN14="","",'Investment Case Asks - Monthly'!AN14),"") | Q14: =IFERROR(IF('Investment Case Asks - Monthly'!BA14="","",'Investment Case Asks - Monthly'!BA14),"") | R14: =IFERROR(IF('Investment Case Asks - Monthly'!BB14="","",'Investment Case Asks - Monthly'!BB14),"")
A15: =IFERROR(IF('Investment Case Asks - Monthly'!A15="","",'Investment Case Asks - Monthly'!A15),"") | B15: =IFERROR(IF('Investment Case Asks - Monthly'!B15="","",'Investment Case Asks - Monthly'!B15),"") | C15: =IFERROR(IF('Investment Case Asks - Monthly'!C15="","",'Investment Case Asks - Monthly'!C15),"") | D15: =IFERROR(IF('Investment Case Asks - Monthly'!D15="","",'Investment Case Asks - Monthly'!D15),"") | E15: =IFERROR(IF('Investment Case Asks - Monthly'!E15="","",'Investment Case Asks - Monthly'!E15),"") | F15: =IFERROR(IF('Investment Case Asks - Monthly'!F15="","",'Investment Case Asks - Monthly'!F15),"") | G15: =IFERROR(IF('Investment Case Asks - Monthly'!G15="","",'Investment Case Asks - Monthly'!G15),"") | H15: =IFERROR(IF('Investment Case Asks - Monthly'!H15="","",'Investment Case Asks - Monthly'!H15),"") | ... N15: =IFERROR(IF('Investment Case Asks - Monthly'!N15="","",'Investment Case Asks - Monthly'!N15),"") | O15: =IFERROR(IF('Investment Case Asks - Monthly'!AA15="","",'Investment Case Asks - Monthly'!AA15),"") | P15: =IFERROR(IF('Investment Case Asks - Monthly'!AN15="","",'Investment Case Asks - Monthly'!AN15),"") | Q15: =IFERROR(IF('Investment Case Asks - Monthly'!BA15="","",'Investment Case Asks - Monthly'!BA15),"") | R15: =IFERROR(IF('Investment Case Asks - Monthly'!BB15="","",'Investment Case Asks - Monthly'!BB15),"")
A16: =IFERROR(IF('Investment Case Asks - Monthly'!A16="","",'Investment Case Asks - Monthly'!A16),"") | B16: =IFERROR(IF('Investment Case Asks - Monthly'!B16="","",'Investment Case Asks - Monthly'!B16),"") | C16: =IFERROR(IF('Investment Case Asks - Monthly'!C16="","",'Investment Case Asks - Monthly'!C16),"") | D16: =IFERROR(IF('Investment Case Asks - Monthly'!D16="","",'Investment Case Asks - Monthly'!D16),"") | E16: =IFERROR(IF('Investment Case Asks - Monthly'!E16="","",'Investment Case Asks - Monthly'!E16),"") | F16: =IFERROR(IF('Investment Case Asks - Monthly'!F16="","",'Investment Case Asks - Monthly'!F16),"") | G16: =IFERROR(IF('Investment Case Asks - Monthly'!G16="","",'Investment Case Asks - Monthly'!G16),"") | H16: =IFERROR(IF('Investment Case Asks - Monthly'!H16="","",'Investment Case Asks - Monthly'!H16),"") | ... N16: =IFERROR(IF('Investment Case Asks - Monthly'!N16="","",'Investment Case Asks - Monthly'!N16),"") | O16: =IFERROR(IF('Investment Case Asks - Monthly'!AA16="","",'Investment Case Asks - Monthly'!AA16),"") | P16: =IFERROR(IF('Investment Case Asks - Monthly'!AN16="","",'Investment Case Asks - Monthly'!AN16),"") | Q16: =IFERROR(IF('Investment Case Asks - Monthly'!BA16="","",'Investment Case Asks - Monthly'!BA16),"") | R16: =IFERROR(IF('Investment Case Asks - Monthly'!BB16="","",'Investment Case Asks - Monthly'!BB16),"")
A17: =IFERROR(IF('Investment Case Asks - Monthly'!A17="","",'Investment Case Asks - Monthly'!A17),"") | B17: =IFERROR(IF('Investment Case Asks - Monthly'!B17="","",'Investment Case Asks - Monthly'!B17),"") | C17: =IFERROR(IF('Investment Case Asks - Monthly'!C17="","",'Investment Case Asks - Monthly'!C17),"") | D17: =IFERROR(IF('Investment Case Asks - Monthly'!D17="","",'Investment Case Asks - Monthly'!D17),"") | E17: =IFERROR(IF('Investment Case Asks - Monthly'!E17="","",'Investment Case Asks - Monthly'!E17),"") | F17: =IFERROR(IF('Investment Case Asks - Monthly'!F17="","",'Investment Case Asks - Monthly'!F17),"") | G17: =IFERROR(IF('Investment Case Asks - Monthly'!G17="","",'Investment Case Asks - Monthly'!G17),"") | H17: =IFERROR(IF('Investment Case Asks - Monthly'!H17="","",'Investment Case Asks - Monthly'!H17),"") | ... N17: =IFERROR(IF('Investment Case Asks - Monthly'!N17="","",'Investment Case Asks - Monthly'!N17),"") | O17: =IFERROR(IF('Investment Case Asks - Monthly'!AA17="","",'Investment Case Asks - Monthly'!AA17),"") | P17: =IFERROR(IF('Investment Case Asks - Monthly'!AN17="","",'Investment Case Asks - Monthly'!AN17),"") | Q17: =IFERROR(IF('Investment Case Asks - Monthly'!BA17="","",'Investment Case Asks - Monthly'!BA17),"") | R17: =IFERROR(IF('Investment Case Asks - Monthly'!BB17="","",'Investment Case Asks - Monthly'!BB17),"")
A18: =IFERROR(IF('Investment Case Asks - Monthly'!A18="","",'Investment Case Asks - Monthly'!A18),"") | B18: =IFERROR(IF('Investment Case Asks - Monthly'!B18="","",'Investment Case Asks - Monthly'!B18),"") | C18: =IFERROR(IF('Investment Case Asks - Monthly'!C18="","",'Investment Case Asks - Monthly'!C18),"") | D18: =IFERROR(IF('Investment Case Asks - Monthly'!D18="","",'Investment Case Asks - Monthly'!D18),"") | E18: =IFERROR(IF('Investment Case Asks - Monthly'!E18="","",'Investment Case Asks - Monthly'!E18),"") | F18: =IFERROR(IF('Investment Case Asks - Monthly'!F18="","",'Investment Case Asks - Monthly'!F18),"") | G18: =IFERROR(IF('Investment Case Asks - Monthly'!G18="","",'Investment Case Asks - Monthly'!G18),"") | H18: =IFERROR(IF('Investment Case Asks - Monthly'!H18="","",'Investment Case Asks - Monthly'!H18),"") | ... N18: =IFERROR(IF('Investment Case Asks - Monthly'!N18="","",'Investment Case Asks - Monthly'!N18),"") | O18: =IFERROR(IF('Investment Case Asks - Monthly'!AA18="","",'Investment Case Asks - Monthly'!AA18),"") | P18: =IFERROR(IF('Investment Case Asks - Monthly'!AN18="","",'Investment Case Asks - Monthly'!AN18),"") | Q18: =IFERROR(IF('Investment Case Asks - Monthly'!BA18="","",'Investment Case Asks - Monthly'!BA18),"") | R18: =IFERROR(IF('Investment Case Asks - Monthly'!BB18="","",'Investment Case Asks - Monthly'!BB18),"")
A19: =IFERROR(IF('Investment Case Asks - Monthly'!A19="","",'Investment Case Asks - Monthly'!A19),"") | B19: =IFERROR(IF('Investment Case Asks - Monthly'!B19="","",'Investment Case Asks - Monthly'!B19),"") | C19: =IFERROR(IF('Investment Case Asks - Monthly'!C19="","",'Investment Case Asks - Monthly'!C19),"") | D19: =IFERROR(IF('Investment Case Asks - Monthly'!D19="","",'Investment Case Asks - Monthly'!D19),"") | E19: =IFERROR(IF('Investment Case Asks - Monthly'!E19="","",'Investment Case Asks - Monthly'!E19),"") | F19: =IFERROR(IF('Investment Case Asks - Monthly'!F19="","",'Investment Case Asks - Monthly'!F19),"") | G19: =IFERROR(IF('Investment Case Asks - Monthly'!G19="","",'Investment Case Asks - Monthly'!G19),"") | H19: =IFERROR(IF('Investment Case Asks - Monthly'!H19="","",'Investment Case Asks - Monthly'!H19),"") | ... N19: =IFERROR(IF('Investment Case Asks - Monthly'!N19="","",'Investment Case Asks - Monthly'!N19),"") | O19: =IFERROR(IF('Investment Case Asks - Monthly'!AA19="","",'Investment Case Asks - Monthly'!AA19),"") | P19: =IFERROR(IF('Investment Case Asks - Monthly'!AN19="","",'Investment Case Asks - Monthly'!AN19),"") | Q19: =IFERROR(IF('Investment Case Asks - Monthly'!BA19="","",'Investment Case Asks - Monthly'!BA19),"") | R19: =IFERROR(IF('Investment Case Asks - Monthly'!BB19="","",'Investment Case Asks - Monthly'!BB19),"")
A20: =IFERROR(IF('Investment Case Asks - Monthly'!A20="","",'Investment Case Asks - Monthly'!A20),"") | B20: =IFERROR(IF('Investment Case Asks - Monthly'!B20="","",'Investment Case Asks - Monthly'!B20),"") | C20: =IFERROR(IF('Investment Case Asks - Monthly'!C20="","",'Investment Case Asks - Monthly'!C20),"") | D20: =IFERROR(IF('Investment Case Asks - Monthly'!D20="","",'Investment Case Asks - Monthly'!D20),"") | E20: =IFERROR(IF('Investment Case Asks - Monthly'!E20="","",'Investment Case Asks - Monthly'!E20),"") | F20: =IFERROR(IF('Investment Case Asks - Monthly'!F20="","",'Investment Case Asks - Monthly'!F20),"") | G20: =IFERROR(IF('Investment Case Asks - Monthly'!G20="","",'Investment Case Asks - Monthly'!G20),"") | H20: =IFERROR(IF('Investment Case Asks - Monthly'!H20="","",'Investment Case Asks - Monthly'!H20),"") | ... N20: =IFERROR(IF('Investment Case Asks - Monthly'!N20="","",'Investment Case Asks - Monthly'!N20),"") | O20: =IFERROR(IF('Investment Case Asks - Monthly'!AA20="","",'Investment Case Asks - Monthly'!AA20),"") | P20: =IFERROR(IF('Investment Case Asks - Monthly'!AN20="","",'Investment Case Asks - Monthly'!AN20),"") | Q20: =IFERROR(IF('Investment Case Asks - Monthly'!BA20="","",'Investment Case Asks - Monthly'!BA20),"") | R20: =IFERROR(IF('Investment Case Asks - Monthly'!BB20="","",'Investment Case Asks - Monthly'!BB20),"")
A22: Total Payroll / Headcount Incremental Spend | G22: =SUM(G5:G20) -> 0 | I22: =SUM(I5:I20) -> 0 | J22: =SUM(J5:J20) -> 0 | K22: =SUM(K5:K20) -> 0 | L22: =SUM(L5:L20) -> 0 | M22: =SUM(M5:M20) -> 0 | N22: =SUM(N5:N20) -> 0 | O22: =SUM(O5:O20) -> 0 | P22: =SUM(P5:P20) -> 0 | Q22: =SUM(Q5:Q20) -> 0
A26: Essentials Bonus / Contract Labor / Non-Payroll Incremental Spend
A27: Expense Description | B27: Type of Expense | C27: Vendor | D27: 2027 Incremental Spend | E27: 2028 Incremental Spend | F27: 2029 Incremental Spend | G27: Notes / Rationale
A28: =IFERROR(IF('Investment Case Asks - Monthly'!A28="","",'Investment Case Asks - Monthly'!A28),"") | B28: =IFERROR(IF('Investment Case Asks - Monthly'!B28="","",'Investment Case Asks - Monthly'!B28),"") | C28: =IFERROR(IF('Investment Case Asks - Monthly'!C28="","",'Investment Case Asks - Monthly'!C28),"") | D28: =IFERROR(IF('Investment Case Asks - Monthly'!Q28="","",'Investment Case Asks - Monthly'!Q28),"") -> 0 | E28: =IFERROR(IF('Investment Case Asks - Monthly'!AD28="","",'Investment Case Asks - Monthly'!AD28),"") -> 0 | F28: =IFERROR(IF('Investment Case Asks - Monthly'!AQ28="","",'Investment Case Asks - Monthly'!AQ28),"") -> 0 | G28: =IFERROR(IF('Investment Case Asks - Monthly'!AR28="","",'Investment Case Asks - Monthly'!AR28),"")
A29: =IFERROR(IF('Investment Case Asks - Monthly'!A29="","",'Investment Case Asks - Monthly'!A29),"") | B29: =IFERROR(IF('Investment Case Asks - Monthly'!B29="","",'Investment Case Asks - Monthly'!B29),"") | C29: =IFERROR(IF('Investment Case Asks - Monthly'!C29="","",'Investment Case Asks - Monthly'!C29),"") | D29: =IFERROR(IF('Investment Case Asks - Monthly'!Q29="","",'Investment Case Asks - Monthly'!Q29),"") -> 0 | E29: =IFERROR(IF('Investment Case Asks - Monthly'!AD29="","",'Investment Case Asks - Monthly'!AD29),"") -> 0 | F29: =IFERROR(IF('Investment Case Asks - Monthly'!AQ29="","",'Investment Case Asks - Monthly'!AQ29),"") -> 0 | G29: =IFERROR(IF('Investment Case Asks - Monthly'!AR29="","",'Investment Case Asks - Monthly'!AR29),"")
A30: =IFERROR(IF('Investment Case Asks - Monthly'!A30="","",'Investment Case Asks - Monthly'!A30),"") | B30: =IFERROR(IF('Investment Case Asks - Monthly'!B30="","",'Investment Case Asks - Monthly'!B30),"") | C30: =IFERROR(IF('Investment Case Asks - Monthly'!C30="","",'Investment Case Asks - Monthly'!C30),"") | D30: =IFERROR(IF('Investment Case Asks - Monthly'!Q30="","",'Investment Case Asks - Monthly'!Q30),"") -> 0 | E30: =IFERROR(IF('Investment Case Asks - Monthly'!AD30="","",'Investment Case Asks - Monthly'!AD30),"") -> 0 | F30: =IFERROR(IF('Investment Case Asks - Monthly'!AQ30="","",'Investment Case Asks - Monthly'!AQ30),"") -> 0 | G30: =IFERROR(IF('Investment Case Asks - Monthly'!AR30="","",'Investment Case Asks - Monthly'!AR30),"")
A31: =IFERROR(IF('Investment Case Asks - Monthly'!A31="","",'Investment Case Asks - Monthly'!A31),"") | B31: =IFERROR(IF('Investment Case Asks - Monthly'!B31="","",'Investment Case Asks - Monthly'!B31),"") | C31: =IFERROR(IF('Investment Case Asks - Monthly'!C31="","",'Investment Case Asks - Monthly'!C31),"") | D31: =IFERROR(IF('Investment Case Asks - Monthly'!Q31="","",'Investment Case Asks - Monthly'!Q31),"") -> 0 | E31: =IFERROR(IF('Investment Case Asks - Monthly'!AD31="","",'Investment Case Asks - Monthly'!AD31),"") -> 0 | F31: =IFERROR(IF('Investment Case Asks - Monthly'!AQ31="","",'Investment Case Asks - Monthly'!AQ31),"") -> 0 | G31: =IFERROR(IF('Investment Case Asks - Monthly'!AR31="","",'Investment Case Asks - Monthly'!AR31),"")
A32: =IFERROR(IF('Investment Case Asks - Monthly'!A32="","",'Investment Case Asks - Monthly'!A32),"") | B32: =IFERROR(IF('Investment Case Asks - Monthly'!B32="","",'Investment Case Asks - Monthly'!B32),"") | C32: =IFERROR(IF('Investment Case Asks - Monthly'!C32="","",'Investment Case Asks - Monthly'!C32),"") | D32: =IFERROR(IF('Investment Case Asks - Monthly'!Q32="","",'Investment Case Asks - Monthly'!Q32),"") -> 0 | E32: =IFERROR(IF('Investment Case Asks - Monthly'!AD32="","",'Investment Case Asks - Monthly'!AD32),"") -> 0 | F32: =IFERROR(IF('Investment Case Asks - Monthly'!AQ32="","",'Investment Case Asks - Monthly'!AQ32),"") -> 0 | G32: =IFERROR(IF('Investment Case Asks - Monthly'!AR32="","",'Investment Case Asks - Monthly'!AR32),"")
A33: =IFERROR(IF('Investment Case Asks - Monthly'!A33="","",'Investment Case Asks - Monthly'!A33),"") | B33: =IFERROR(IF('Investment Case Asks - Monthly'!B33="","",'Investment Case Asks - Monthly'!B33),"") | C33: =IFERROR(IF('Investment Case Asks - Monthly'!C33="","",'Investment Case Asks - Monthly'!C33),"") | D33: =IFERROR(IF('Investment Case Asks - Monthly'!Q33="","",'Investment Case Asks - Monthly'!Q33),"") -> 0 | E33: =IFERROR(IF('Investment Case Asks - Monthly'!AD33="","",'Investment Case Asks - Monthly'!AD33),"") -> 0 | F33: =IFERROR(IF('Investment Case Asks - Monthly'!AQ33="","",'Investment Case Asks - Monthly'!AQ33),"") -> 0 | G33: =IFERROR(IF('Investment Case Asks - Monthly'!AR33="","",'Investment Case Asks - Monthly'!AR33),"")
A34: =IFERROR(IF('Investment Case Asks - Monthly'!A34="","",'Investment Case Asks - Monthly'!A34),"") | B34: =IFERROR(IF('Investment Case Asks - Monthly'!B34="","",'Investment Case Asks - Monthly'!B34),"") | C34: =IFERROR(IF('Investment Case Asks - Monthly'!C34="","",'Investment Case Asks - Monthly'!C34),"") | D34: =IFERROR(IF('Investment Case Asks - Monthly'!Q34="","",'Investment Case Asks - Monthly'!Q34),"") -> 0 | E34: =IFERROR(IF('Investment Case Asks - Monthly'!AD34="","",'Investment Case Asks - Monthly'!AD34),"") -> 0 | F34: =IFERROR(IF('Investment Case Asks - Monthly'!AQ34="","",'Investment Case Asks - Monthly'!AQ34),"") -> 0 | G34: =IFERROR(IF('Investment Case Asks - Monthly'!AR34="","",'Investment Case Asks - Monthly'!AR34),"")
A35: =IFERROR(IF('Investment Case Asks - Monthly'!A35="","",'Investment Case Asks - Monthly'!A35),"") | B35: =IFERROR(IF('Investment Case Asks - Monthly'!B35="","",'Investment Case Asks - Monthly'!B35),"") | C35: =IFERROR(IF('Investment Case Asks - Monthly'!C35="","",'Investment Case Asks - Monthly'!C35),"") | D35: =IFERROR(IF('Investment Case Asks - Monthly'!Q35="","",'Investment Case Asks - Monthly'!Q35),"") -> 0 | E35: =IFERROR(IF('Investment Case Asks - Monthly'!AD35="","",'Investment Case Asks - Monthly'!AD35),"") -> 0 | F35: =IFERROR(IF('Investment Case Asks - Monthly'!AQ35="","",'Investment Case Asks - Monthly'!AQ35),"") -> 0 | G35: =IFERROR(IF('Investment Case Asks - Monthly'!AR35="","",'Investment Case Asks - Monthly'!AR35),"")
A36: =IFERROR(IF('Investment Case Asks - Monthly'!A36="","",'Investment Case Asks - Monthly'!A36),"") | B36: =IFERROR(IF('Investment Case Asks - Monthly'!B36="","",'Investment Case Asks - Monthly'!B36),"") | C36: =IFERROR(IF('Investment Case Asks - Monthly'!C36="","",'Investment Case Asks - Monthly'!C36),"") | D36: =IFERROR(IF('Investment Case Asks - Monthly'!Q36="","",'Investment Case Asks - Monthly'!Q36),"") -> 0 | E36: =IFERROR(IF('Investment Case Asks - Monthly'!AD36="","",'Investment Case Asks - Monthly'!AD36),"") -> 0 | F36: =IFERROR(IF('Investment Case Asks - Monthly'!AQ36="","",'Investment Case Asks - Monthly'!AQ36),"") -> 0 | G36: =IFERROR(IF('Investment Case Asks - Monthly'!AR36="","",'Investment Case Asks - Monthly'!AR36),"")
A37: =IFERROR(IF('Investment Case Asks - Monthly'!A37="","",'Investment Case Asks - Monthly'!A37),"") | B37: =IFERROR(IF('Investment Case Asks - Monthly'!B37="","",'Investment Case Asks - Monthly'!B37),"") | C37: =IFERROR(IF('Investment Case Asks - Monthly'!C37="","",'Investment Case Asks - Monthly'!C37),"") | D37: =IFERROR(IF('Investment Case Asks - Monthly'!Q37="","",'Investment Case Asks - Monthly'!Q37),"") -> 0 | E37: =IFERROR(IF('Investment Case Asks - Monthly'!AD37="","",'Investment Case Asks - Monthly'!AD37),"") -> 0 | F37: =IFERROR(IF('Investment Case Asks - Monthly'!AQ37="","",'Investment Case Asks - Monthly'!AQ37),"") -> 0 | G37: =IFERROR(IF('Investment Case Asks - Monthly'!AR37="","",'Investment Case Asks - Monthly'!AR37),"")
A38: =IFERROR(IF('Investment Case Asks - Monthly'!A38="","",'Investment Case Asks - Monthly'!A38),"") | B38: =IFERROR(IF('Investment Case Asks - Monthly'!B38="","",'Investment Case Asks - Monthly'!B38),"") | C38: =IFERROR(IF('Investment Case Asks - Monthly'!C38="","",'Investment Case Asks - Monthly'!C38),"") | D38: =IFERROR(IF('Investment Case Asks - Monthly'!Q38="","",'Investment Case Asks - Monthly'!Q38),"") -> 0 | E38: =IFERROR(IF('Investment Case Asks - Monthly'!AD38="","",'Investment Case Asks - Monthly'!AD38),"") -> 0 | F38: =IFERROR(IF('Investment Case Asks - Monthly'!AQ38="","",'Investment Case Asks - Monthly'!AQ38),"") -> 0 | G38: =IFERROR(IF('Investment Case Asks - Monthly'!AR38="","",'Investment Case Asks - Monthly'!AR38),"")
A39: =IFERROR(IF('Investment Case Asks - Monthly'!A39="","",'Investment Case Asks - Monthly'!A39),"") | B39: =IFERROR(IF('Investment Case Asks - Monthly'!B39="","",'Investment Case Asks - Monthly'!B39),"") | C39: =IFERROR(IF('Investment Case Asks - Monthly'!C39="","",'Investment Case Asks - Monthly'!C39),"") | D39: =IFERROR(IF('Investment Case Asks - Monthly'!Q39="","",'Investment Case Asks - Monthly'!Q39),"") -> 0 | E39: =IFERROR(IF('Investment Case Asks - Monthly'!AD39="","",'Investment Case Asks - Monthly'!AD39),"") -> 0 | F39: =IFERROR(IF('Investment Case Asks - Monthly'!AQ39="","",'Investment Case Asks - Monthly'!AQ39),"") -> 0 | G39: =IFERROR(IF('Investment Case Asks - Monthly'!AR39="","",'Investment Case Asks - Monthly'!AR39),"")
... A42: =IFERROR(IF('Investment Case Asks - Monthly'!A42="","",'Investment Case Asks - Monthly'!A42),"") | B42: =IFERROR(IF('Investment Case Asks - Monthly'!B42="","",'Investment Case Asks - Monthly'!B42),"") | C42: =IFERROR(IF('Investment Case Asks - Monthly'!C42="","",'Investment Case Asks - Monthly'!C42),"") | D42: =IFERROR(IF('Investment Case Asks - Monthly'!Q42="","",'Investment Case Asks - Monthly'!Q42),"") -> 0 | E42: =IFERROR(IF('Investment Case Asks - Monthly'!AD42="","",'Investment Case Asks - Monthly'!AD42),"") -> 0 | F42: =IFERROR(IF('Investment Case Asks - Monthly'!AQ42="","",'Investment Case Asks - Monthly'!AQ42),"") -> 0 | G42: =IFERROR(IF('Investment Case Asks - Monthly'!AR42="","",'Investment Case Asks - Monthly'!AR42),"")
A44: Total Essentials Bonus / Contract Labor / Non-Payroll Incremental Spend | D44: =SUM(D28:D42) -> 0 | E44: =SUM(E28:E42) -> 0 | F44: =SUM(F28:F42) -> 0

Sheet Investment Case Asks - Monthly
A1: Investment Case Asks - Incremental Spend Input
A3: Payroll / Headcount Incremental Spend
A4: Job Title | B4: Job Level | C4: Role / Hire | D4: Location (City/Country) | E4: Key Job Responsibilities | F4: Hire Date | G4: Base Salary | H4: Bonus % | I4: Bonus | J4: Payroll Taxes | K4: Benefits | L4: Vacation | M4: Other | N4: Annualized Spend | O4: Jan-27 | P4: Feb-27 | Q4: Mar-27 | R4: Apr-27 | S4: May-27 | T4: Jun-27 | U4: Jul-27 | V4: Aug-27 | W4: Sep-27 | X4: Oct-27 | Y4: Nov-27 | Z4: Dec-27 | AA4: 2027 Incremental Spend | AB4: Jan-28 | AC4: Feb-28 | AD4: Mar-28 | AE4: Apr-28 | AF4: May-28 | AG4: Jun-28 | AH4: Jul-28 | AI4: Aug-28 | AJ4: Sep-28 | AK4: Oct-28 | AL4: Nov-28 | AM4: Dec-28 | AN4: 2028 Incremental Spend | AO4: Jan-29 | AP4: Feb-29 | AQ4: Mar-29 | AR4: Apr-29 | AS4: May-29 | AT4: Jun-29 | AU4: Jul-29 | AV4: Aug-29 | AW4: Sep-29 | AX4: Oct-29 | AY4: Nov-29 | AZ4: Dec-29 | BA4: 2029 Incremental Spend | BB4: Notes / Rationale
I5: =IF(COUNTA($A5:$H5)>0,IFERROR($G5*$H5,0),"") | J5: =IF(COUNTA($A5:$H5)>0,IFERROR($G5*Summary!$C$46/Summary!$C$43,0),"") | K5: =IF(COUNTA($A5:$H5)>0,IFERROR($G5*Summary!$C$47/Summary!$C$43,0),"") | L5: =IF(COUNTA($A5:$H5)>0,IFERROR($G5*Summary!$C$48/Summary!$C$43,0),"") | M5: =IF(COUNTA($A5:$H5)>0,IFERROR($G5*Summary!$C$49/Summary!$C$43,0),"") | N5: =IF(COUNTA($A5:$H5)>0,IFERROR($G5,0)+SUM(I5:M5),"") | O5: =_xlfn.LET(_xlpm.m,IF(ISNUMBER(O$4),DATE(YEAR(O$4),MONTH(O$4),1),DATEVALUE("1-"&O$4)),IF(OR(COUNTA($A5:$F5)>0,$G5<>""),$N5/12*IF($F5="",1,MAX(0,(EOMONTH(_xlpm.m,0)-MAX($F5,_xlpm.m)+1)/(EOMONTH(_xlpm.m,0)-_xlpm.m+1))),"")) | P5: =_xlfn.LET(_xlpm.m,IF(ISNUMBER(P$4),DATE(YEAR(P$4),MONTH(P$4),1),DATEVALUE("1-"&P$4)),IF(OR(COUNTA($A5:$F5)>0,$G5<>""),$N5/12*IF($F5="",1,MAX(0,(EOMONTH(_xlpm.m,0)-MAX($F5,_xlpm.m)+1)/(EOMONTH(_xlpm.m,0)-_xlpm.m+1))),"")) | Q5: =_xlfn.LET(_xlpm.m,IF(ISNUMBER(Q$4),DATE(YEAR(Q$4),MONTH(Q$4),1),DATEVALUE("1-"&Q$4)),IF(OR(COUNTA($A5:$F5)>0,$G5<>""),$N5/12*IF($F5="",1,MAX(0,(EOMONTH(_xlpm.m,0)-MAX($F5,_xlpm.m)+1)/(EOMONTH(_xlpm.m,0)-_xlpm.m+1))),"")) | R5: =_xlfn.LET(_xlpm.m,IF(ISNUMBER(R$4),DATE(YEAR(R$4),MONTH(R$4),1),DATEVALUE("1-"&R$4)),IF(OR(COUNTA($A5:$F5)>0,$G5<>""),$N5/12*IF($F5="",1,MAX(0,(EOMONTH(_xlpm.m,0)-MAX($F5,_xlpm.m)+1)/(EOMONTH(_xlpm.m,0)-_xlpm.m+1))),"")) | S5: =_xlfn.LET(_xlpm.m,IF(ISNUMBER(S$4),DATE(YEAR(S$4),MONTH(S$4),1),DATEVALUE("1-"&S$4)),IF(OR(COUNTA($A5:$F5)>0,$G5<>""),$N5/12*IF($F5="",1,MAX(0,(EOMONTH(_xlpm.m,0)-MAX($F5,_xlpm.m)+1)/(EOMONTH(_xlpm.m,0)-_xlpm.m+1))),"")) | T5: =_xlfn.LET(_xlpm.m,IF(ISNUMBER(T$4),DATE(YEAR(T$4),MONTH(T$4),1),DATEVALUE("1-"&T$4)),IF(OR(COUNTA($A5:$F5)>0,$G5<>""),$N5/12*IF($F5="",1,MAX(0,(EOMONTH(_xlpm.m,0)-MAX($F5,_xlpm.m)+1)/(EOMONTH(_xlpm.m,0)-_xlpm.m+1))),"")) | U5: =_xlfn.LET(_xlpm.m,IF(ISNUMBER(U$4),DATE(YEAR(U$4),MONTH(U$4),1),DATEVALUE("1-"&U$4)),IF(OR(COUNTA($A5:$F5)>0,$G5<>""),$N5/12*IF($F5="",1,MAX(0,(EOMONTH(_xlpm.m,0)-MAX($F5,_xlpm.m)+1)/(EOMONTH(_xlpm.m,0)-_xlpm.m+1))),"")) | V5: =_xlfn.LET(_xlpm.m,IF(ISNUMBER(V$4),DATE(YEAR(V$4),MONTH(V$4),1),DATEVALUE("1-"&V$4)),IF(OR(COUNTA($A5:$F5)>0,$G5<>""),$N5/12*IF($F5="",1,MAX(0,(EOMONTH(_xlpm.m,0)-MAX($F5,_xlpm.m)+1)/(EOMONTH(_xlpm.m,0)-_xlpm.m+1))),"")) | ... Z5: =_xlfn.LET(_xlpm.m,IF(ISNUMBER(Z$4),DATE(YEAR(Z$4),MONTH(Z$4),1),DATEVALUE("1-"&Z$4)),IF(OR(COUNTA($A5:$F5)>0,$G5<>""),$N5/12*IF($F5="",1,MAX(0,(EOMONTH(_xlpm.m,0)-MAX($F5,_xlpm.m)+1)/(EOMONTH(_xlpm.m,0)-_xlpm.m+1))),"")) | AA5: =IF(OR(COUNTA($A5:$F5)>0,$G5<>""),SUM(O5:Z5),"") | AB5: =_xlfn.LET(_xlpm.m,IF(ISNUMBER(AB$4),DATE(YEAR(AB$4),MONTH(AB$4),1),DATEVALUE("1-"&AB$4)),IF(OR(COUNTA($A5:$F5)>0,$G5<>""),$N5/12*IF($F5="",1,MAX(0,(EOMONTH(_xlpm.m,0)-MAX($F5,_xlpm.m)+1)/(EOMONTH(_xlpm.m,0)-_xlpm.m+1))),"")) | AC5: =_xlfn.LET(_xlpm.m,IF(ISNUMBER(AC$4),DATE(YEAR(AC$4),MONTH(AC$4),1),DATEVALUE("1-"&AC$4)),IF(OR(COUNTA($A5:$F5)>0,$G5<>""),$N5/12*IF($F5="",1,MAX(0,(EOMONTH(_xlpm.m,0)-MAX($F5,_xlpm.m)+1)/(EOMONTH(_xlpm.m,0)-_xlpm.m+1))),"")) | AD5: =_xlfn.LET(_xlpm.m,IF(ISNUMBER(AD$4),DATE(YEAR(AD$4),MONTH(AD$4),1),DATEVALUE("1-"&AD$4)),IF(OR(COUNTA($A5:$F5)>0,$G5<>""),$N5/12*IF($F5="",1,MAX(0,(EOMONTH(_xlpm.m,0)-MAX($F5,_xlpm.m)+1)/(EOMONTH(_xlpm.m,0)-_xlpm.m+1))),"")) | AE5: =_xlfn.LET(_xlpm.m,IF(ISNUMBER(AE$4),DATE(YEAR(AE$4),MONTH(AE$4),1),DATEVALUE("1-"&AE$4)),IF(OR(COUNTA($A5:$F5)>0,$G5<>""),$N5/12*IF($F5="",1,MAX(0,(EOMONTH(_xlpm.m,0)-MAX($F5,_xlpm.m)+1)/(EOMONTH(_xlpm.m,0)-_xlpm.m+1))),"")) | AF5: =_xlfn.LET(_xlpm.m,IF(ISNUMBER(AF$4),DATE(YEAR(AF$4),MONTH(AF$4),1),DATEVALUE("1-"&AF$4)),IF(OR(COUNTA($A5:$F5)>0,$G5<>""),$N5/12*IF($F5="",1,MAX(0,(EOMONTH(_xlpm.m,0)-MAX($F5,_xlpm.m)+1)/(EOMONTH(_xlpm.m,0)-_xlpm.m+1))),"")) | AG5: =_xlfn.LET(_xlpm.m,IF(ISNUMBER(AG$4),DATE(YEAR(AG$4),MONTH(AG$4),1),DATEVALUE("1-"&AG$4)),IF(OR(COUNTA($A5:$F5)>0,$G5<>""),$N5/12*IF($F5="",1,MAX(0,(EOMONTH(_xlpm.m,0)-MAX($F5,_xlpm.m)+1)/(EOMONTH(_xlpm.m,0)-_xlpm.m+1))),"")) | AH5: =_xlfn.LET(_xlpm.m,IF(ISNUMBER(AH$4),DATE(YEAR(AH$4),MONTH(AH$4),1),DATEVALUE("1-"&AH$4)),IF(OR(COUNTA($A5:$F5)>0,$G5<>""),$N5/12*IF($F5="",1,MAX(0,(EOMONTH(_xlpm.m,0)-MAX($F5,_xlpm.m)+1)/(EOMONTH(_xlpm.m,0)-_xlpm.m+1))),"")) | AI5: =_xlfn.LET(_xlpm.m,IF(ISNUMBER(AI$4),DATE(YEAR(AI$4),MONTH(AI$4),1),DATEVALUE("1-"&AI$4)),IF(OR(COUNTA($A5:$F5)>0,$G5<>""),$N5/12*IF($F5="",1,MAX(0,(EOMONTH(_xlpm.m,0)-MAX($F5,_xlpm.m)+1)/(EOMONTH(_xlpm.m,0)-_xlpm.m+1))),"")) | ... AM5: =_xlfn.LET(_xlpm.m,IF(ISNUMBER(AM$4),DATE(YEAR(AM$4),MONTH(AM$4),1),DATEVALUE("1-"&AM$4)),IF(OR(COUNTA($A5:$F5)>0,$G5<>""),$N5/12*IF($F5="",1,MAX(0,(EOMONTH(_xlpm.m,0)-MAX($F5,_xlpm.m)+1)/(EOMONTH(_xlpm.m,0)-_xlpm.m+1))),"")) | AN5: =IF(OR(COUNTA($A5:$F5)>0,$G5<>""),SUM(AB5:AM5),"") | AO5: =_xlfn.LET(_xlpm.m,IF(ISNUMBER(AO$4),DATE(YEAR(AO$4),MONTH(AO$4),1),DATEVALUE("1-"&AO$4)),IF(OR(COUNTA($A5:$F5)>0,$G5<>""),$N5/12*IF($F5="",1,MAX(0,(EOMONTH(_xlpm.m,0)-MAX($F5,_xlpm.m)+1)/(EOMONTH(_xlpm.m,0)-_xlpm.m+1))),"")) | AP5: =_xlfn.LET(_xlpm.m,IF(ISNUMBER(AP$4),DATE(YEAR(AP$4),MONTH(AP$4),1),DATEVALUE("1-"&AP$4)),IF(OR(COUNTA($A5:$F5)>0,$G5<>""),$N5/12*IF($F5="",1,MAX(0,(EOMONTH(_xlpm.m,0)-MAX($F5,_xlpm.m)+1)/(EOMONTH(_xlpm.m,0)-_xlpm.m+1))),"")) | AQ5: =_xlfn.LET(_xlpm.m,IF(ISNUMBER(AQ$4),DATE(YEAR(AQ$4),MONTH(AQ$4),1),DATEVALUE("1-"&AQ$4)),IF(OR(COUNTA($A5:$F5)>0,$G5<>""),$N5/12*IF($F5="",1,MAX(0,(EOMONTH(_xlpm.m,0)-MAX($F5,_xlpm.m)+1)/(EOMONTH(_xlpm.m,0)-_xlpm.m+1))),"")) | AR5: =_xlfn.LET(_xlpm.m,IF(ISNUMBER(AR$4),DATE(YEAR(AR$4),MONTH(AR$4),1),DATEVALUE("1-"&AR$4)),IF(OR(COUNTA($A5:$F5)>0,$G5<>""),$N5/12*IF($F5="",1,MAX(0,(EOMONTH(_xlpm.m,0)-MAX($F5,_xlpm.m)+1)/(EOMONTH(_xlpm.m,0)-_xlpm.m+1))),"")) | AS5: =_xlfn.LET(_xlpm.m,IF(ISNUMBER(AS$4),DATE(YEAR(AS$4),MONTH(AS$4),1),DATEVALUE("1-"&AS$4)),IF(OR(COUNTA($A5:$F5)>0,$G5<>""),$N5/12*IF($F5="",1,MAX(0,(EOMONTH(_xlpm.m,0)-MAX($F5,_xlpm.m)+1)/(EOMONTH(_xlpm.m,0)-_xlpm.m+1))),"")) | AT5: =_xlfn.LET(_xlpm.m,IF(ISNUMBER(AT$4),DATE(YEAR(AT$4),MONTH(AT$4),1),DATEVALUE("1-"&AT$4)),IF(OR(COUNTA($A5:$F5)>0,$G5<>""),$N5/12*IF($F5="",1,MAX(0,(EOMONTH(_xlpm.m,0)-MAX($F5,_xlpm.m)+1)/(EOMONTH(_xlpm.m,0)-_xlpm.m+1))),"")) | AU5: =_xlfn.LET(_xlpm.m,IF(ISNUMBER(AU$4),DATE(YEAR(AU$4),MONTH(AU$4),1),DATEVALUE("1-"&AU$4)),IF(OR(COUNTA($A5:$F5)>0,$G5<>""),$N5/12*IF($F5="",1,MAX(0,(EOMONTH(_xlpm.m,0)-MAX($F5,_xlpm.m)+1)/(EOMONTH(_xlpm.m,0)-_xlpm.m+1))),"")) | AV5: =_xlfn.LET(_xlpm.m,IF(ISNUMBER(AV$4),DATE(YEAR(AV$4),MONTH(AV$4),1),DATEVALUE("1-"&AV$4)),IF(OR(COUNTA($A5:$F5)>0,$G5<>""),$N5/12*IF($F5="",1,MAX(0,(EOMONTH(_xlpm.m,0)-MAX($F5,_xlpm.m)+1)/(EOMONTH(_xlpm.m,0)-_xlpm.m+1))),"")) | ... AZ5: =_xlfn.LET(_xlpm.m,IF(ISNUMBER(AZ$4),DATE(YEAR(AZ$4),MONTH(AZ$4),1),DATEVALUE("1-"&AZ$4)),IF(OR(COUNTA($A5:$F5)>0,$G5<>""),$N5/12*IF($F5="",1,MAX(0,(EOMONTH(_xlpm.m,0)-MAX($F5,_xlpm.m)+1)/(EOMONTH(_xlpm.m,0)-_xlpm.m+1))),"")) | BA5: =IF(OR(COUNTA($A5:$F5)>0,$G5<>""),SUM(AO5:AZ5),"")
I6: =IF(COUNTA($A6:$H6)>0,IFERROR($G6*$H6,0),"") | J6: =IF(COUNTA($A6:$H6)>0,IFERROR($G6*Summary!$C$46/Summary!$C$43,0),"") | K6: =IF(COUNTA($A6:$H6)>0,IFERROR($G6*Summary!$C$47/Summary!$C$43,0),"") | L6: =IF(COUNTA($A6:$H6)>0,IFERROR($G6*Summary!$C$48/Summary!$C$43,0),"") | M6: =IF(COUNTA($A6:$H6)>0,IFERROR($G6*Summary!$C$49/Summary!$C$43,0),"") | N6: =IF(COUNTA($A6:$H6)>0,IFERROR($G6,0)+SUM(I6:M6),"") | O6: =_xlfn.LET(_xlpm.m,IF(ISNUMBER(O$4),DATE(YEAR(O$4),MONTH(O$4),1),DATEVALUE("1-"&O$4)),IF(OR(COUNTA($A6:$F6)>0,$G6<>""),$N6/12*IF($F6="",1,MAX(0,(EOMONTH(_xlpm.m,0)-MAX($F6,_xlpm.m)+1)/(EOMONTH(_xlpm.m,0)-_xlpm.m+1))),"")) | P6: =_xlfn.LET(_xlpm.m,IF(ISNUMBER(P$4),DATE(YEAR(P$4),MONTH(P$4),1),DATEVALUE("1-"&P$4)),IF(OR(COUNTA($A6:$F6)>0,$G6<>""),$N6/12*IF($F6="",1,MAX(0,(EOMONTH(_xlpm.m,0)-MAX($F6,_xlpm.m)+1)/(EOMONTH(_xlpm.m,0)-_xlpm.m+1))),"")) | Q6: =_xlfn.LET(_xlpm.m,IF(ISNUMBER(Q$4),DATE(YEAR(Q$4),MONTH(Q$4),1),DATEVALUE("1-"&Q$4)),IF(OR(COUNTA($A6:$F6)>0,$G6<>""),$N6/12*IF($F6="",1,MAX(0,(EOMONTH(_xlpm.m,0)-MAX($F6,_xlpm.m)+1)/(EOMONTH(_xlpm.m,0)-_xlpm.m+1))),"")) | R6: =_xlfn.LET(_xlpm.m,IF(ISNUMBER(R$4),DATE(YEAR(R$4),MONTH(R$4),1),DATEVALUE("1-"&R$4)),IF(OR(COUNTA($A6:$F6)>0,$G6<>""),$N6/12*IF($F6="",1,MAX(0,(EOMONTH(_xlpm.m,0)-MAX($F6,_xlpm.m)+1)/(EOMONTH(_xlpm.m,0)-_xlpm.m+1))),"")) | S6: =_xlfn.LET(_xlpm.m,IF(ISNUMBER(S$4),DATE(YEAR(S$4),MONTH(S$4),1),DATEVALUE("1-"&S$4)),IF(OR(COUNTA($A6:$F6)>0,$G6<>""),$N6/12*IF($F6="",1,MAX(0,(EOMONTH(_xlpm.m,0)-MAX($F6,_xlpm.m)+1)/(EOMONTH(_xlpm.m,0)-_xlpm.m+1))),"")) | T6: =_xlfn.LET(_xlpm.m,IF(ISNUMBER(T$4),DATE(YEAR(T$4),MONTH(T$4),1),DATEVALUE("1-"&T$4)),IF(OR(COUNTA($A6:$F6)>0,$G6<>""),$N6/12*IF($F6="",1,MAX(0,(EOMONTH(_xlpm.m,0)-MAX($F6,_xlpm.m)+1)/(EOMONTH(_xlpm.m,0)-_xlpm.m+1))),"")) | U6: =_xlfn.LET(_xlpm.m,IF(ISNUMBER(U$4),DATE(YEAR(U$4),MONTH(U$4),1),DATEVALUE("1-"&U$4)),IF(OR(COUNTA($A6:$F6)>0,$G6<>""),$N6/12*IF($F6="",1,MAX(0,(EOMONTH(_xlpm.m,0)-MAX($F6,_xlpm.m)+1)/(EOMONTH(_xlpm.m,0)-_xlpm.m+1))),"")) | V6: =_xlfn.LET(_xlpm.m,IF(ISNUMBER(V$4),DATE(YEAR(V$4),MONTH(V$4),1),DATEVALUE("1-"&V$4)),IF(OR(COUNTA($A6:$F6)>0,$G6<>""),$N6/12*IF($F6="",1,MAX(0,(EOMONTH(_xlpm.m,0)-MAX($F6,_xlpm.m)+1)/(EOMONTH(_xlpm.m,0)-_xlpm.m+1))),"")) | ... Z6: =_xlfn.LET(_xlpm.m,IF(ISNUMBER(Z$4),DATE(YEAR(Z$4),MONTH(Z$4),1),DATEVALUE("1-"&Z$4)),IF(OR(COUNTA($A6:$F6)>0,$G6<>""),$N6/12*IF($F6="",1,MAX(0,(EOMONTH(_xlpm.m,0)-MAX($F6,_xlpm.m)+1)/(EOMONTH(_xlpm.m,0)-_xlpm.m+1))),"")) | AA6: =IF(COUNTA($A6:$H6)>0,SUM(O6:Z6),"") | AB6: =_xlfn.LET(_xlpm.m,IF(ISNUMBER(AB$4),DATE(YEAR(AB$4),MONTH(AB$4),1),DATEVALUE("1-"&AB$4)),IF(OR(COUNTA($A6:$F6)>0,$G6<>""),$N6/12*IF($F6="",1,MAX(0,(EOMONTH(_xlpm.m,0)-MAX($F6,_xlpm.m)+1)/(EOMONTH(_xlpm.m,0)-_xlpm.m+1))),"")) | AC6: =_xlfn.LET(_xlpm.m,IF(ISNUMBER(AC$4),DATE(YEAR(AC$4),MONTH(AC$4),1),DATEVALUE("1-"&AC$4)),IF(OR(COUNTA($A6:$F6)>0,$G6<>""),$N6/12*IF($F6="",1,MAX(0,(EOMONTH(_xlpm.m,0)-MAX($F6,_xlpm.m)+1)/(EOMONTH(_xlpm.m,0)-_xlpm.m+1))),"")) | AD6: =_xlfn.LET(_xlpm.m,IF(ISNUMBER(AD$4),DATE(YEAR(AD$4),MONTH(AD$4),1),DATEVALUE("1-"&AD$4)),IF(OR(COUNTA($A6:$F6)>0,$G6<>""),$N6/12*IF($F6="",1,MAX(0,(EOMONTH(_xlpm.m,0)-MAX($F6,_xlpm.m)+1)/(EOMONTH(_xlpm.m,0)-_xlpm.m+1))),"")) | AE6: =_xlfn.LET(_xlpm.m,IF(ISNUMBER(AE$4),DATE(YEAR(AE$4),MONTH(AE$4),1),DATEVALUE("1-"&AE$4)),IF(OR(COUNTA($A6:$F6)>0,$G6<>""),$N6/12*IF($F6="",1,MAX(0,(EOMONTH(_xlpm.m,0)-MAX($F6,_xlpm.m)+1)/(EOMONTH(_xlpm.m,0)-_xlpm.m+1))),"")) | AF6: =_xlfn.LET(_xlpm.m,IF(ISNUMBER(AF$4),DATE(YEAR(AF$4),MONTH(AF$4),1),DATEVALUE("1-"&AF$4)),IF(OR(COUNTA($A6:$F6)>0,$G6<>""),$N6/12*IF($F6="",1,MAX(0,(EOMONTH(_xlpm.m,0)-MAX($F6,_xlpm.m)+1)/(EOMONTH(_xlpm.m,0)-_xlpm.m+1))),"")) | AG6: =_xlfn.LET(_xlpm.m,IF(ISNUMBER(AG$4),DATE(YEAR(AG$4),MONTH(AG$4),1),DATEVALUE("1-"&AG$4)),IF(OR(COUNTA($A6:$F6)>0,$G6<>""),$N6/12*IF($F6="",1,MAX(0,(EOMONTH(_xlpm.m,0)-MAX($F6,_xlpm.m)+1)/(EOMONTH(_xlpm.m,0)-_xlpm.m+1))),"")) | AH6: =_xlfn.LET(_xlpm.m,IF(ISNUMBER(AH$4),DATE(YEAR(AH$4),MONTH(AH$4),1),DATEVALUE("1-"&AH$4)),IF(OR(COUNTA($A6:$F6)>0,$G6<>""),$N6/12*IF($F6="",1,MAX(0,(EOMONTH(_xlpm.m,0)-MAX($F6,_xlpm.m)+1)/(EOMONTH(_xlpm.m,0)-_xlpm.m+1))),"")) | AI6: =_xlfn.LET(_xlpm.m,IF(ISNUMBER(AI$4),DATE(YEAR(AI$4),MONTH(AI$4),1),DATEVALUE("1-"&AI$4)),IF(OR(COUNTA($A6:$F6)>0,$G6<>""),$N6/12*IF($F6="",1,MAX(0,(EOMONTH(_xlpm.m,0)-MAX($F6,_xlpm.m)+1)/(EOMONTH(_xlpm.m,0)-_xlpm.m+1))),"")) | ... AM6: =_xlfn.LET(_xlpm.m,IF(ISNUMBER(AM$4),DATE(YEAR(AM$4),MONTH(AM$4),1),DATEVALUE("1-"&AM$4)),IF(OR(COUNTA($A6:$F6)>0,$G6<>""),$N6/12*IF($F6="",1,MAX(0,(EOMONTH(_xlpm.m,0)-MAX($F6,_xlpm.m)+1)/(EOMONTH(_xlpm.m,0)-_xlpm.m+1))),"")) | AN6: =IF(COUNTA($A6:$H6)>0,SUM(AB6:AM6),"") | AO6: =_xlfn.LET(_xlpm.m,IF(ISNUMBER(AO$4),DATE(YEAR(AO$4),MONTH(AO$4),1),DATEVALUE("1-"&AO$4)),IF(OR(COUNTA($A6:$F6)>0,$G6<>""),$N6/12*IF($F6="",1,MAX(0,(EOMONTH(_xlpm.m,0)-MAX($F6,_xlpm.m)+1)/(EOMONTH(_xlpm.m,0)-_xlpm.m+1))),"")) | AP6: =_xlfn.LET(_xlpm.m,IF(ISNUMBER(AP$4),DATE(YEAR(AP$4),MONTH(AP$4),1),DATEVALUE("1-"&AP$4)),IF(OR(COUNTA($A6:$F6)>0,$G6<>""),$N6/12*IF($F6="",1,MAX(0,(EOMONTH(_xlpm.m,0)-MAX($F6,_xlpm.m)+1)/(EOMONTH(_xlpm.m,0)-_xlpm.m+1))),"")) | AQ6: =_xlfn.LET(_xlpm.m,IF(ISNUMBER(AQ$4),DATE(YEAR(AQ$4),MONTH(AQ$4),1),DATEVALUE("1-"&AQ$4)),IF(OR(COUNTA($A6:$F6)>0,$G6<>""),$N6/12*IF($F6="",1,MAX(0,(EOMONTH(_xlpm.m,0)-MAX($F6,_xlpm.m)+1)/(EOMONTH(_xlpm.m,0)-_xlpm.m+1))),"")) | AR6: =_xlfn.LET(_xlpm.m,IF(ISNUMBER(AR$4),DATE(YEAR(AR$4),MONTH(AR$4),1),DATEVALUE("1-"&AR$4)),IF(OR(COUNTA($A6:$F6)>0,$G6<>""),$N6/12*IF($F6="",1,MAX(0,(EOMONTH(_xlpm.m,0)-MAX($F6,_xlpm.m)+1)/(EOMONTH(_xlpm.m,0)-_xlpm.m+1))),"")) | AS6: =_xlfn.LET(_xlpm.m,IF(ISNUMBER(AS$4),DATE(YEAR(AS$4),MONTH(AS$4),1),DATEVALUE("1-"&AS$4)),IF(OR(COUNTA($A6:$F6)>0,$G6<>""),$N6/12*IF($F6="",1,MAX(0,(EOMONTH(_xlpm.m,0)-MAX($F6,_xlpm.m)+1)/(EOMONTH(_xlpm.m,0)-_xlpm.m+1))),"")) | AT6: =_xlfn.LET(_xlpm.m,IF(ISNUMBER(AT$4),DATE(YEAR(AT$4),MONTH(AT$4),1),DATEVALUE("1-"&AT$4)),IF(OR(COUNTA($A6:$F6)>0,$G6<>""),$N6/12*IF($F6="",1,MAX(0,(EOMONTH(_xlpm.m,0)-MAX($F6,_xlpm.m)+1)/(EOMONTH(_xlpm.m,0)-_xlpm.m+1))),"")) | AU6: =_xlfn.LET(_xlpm.m,IF(ISNUMBER(AU$4),DATE(YEAR(AU$4),MONTH(AU$4),1),DATEVALUE("1-"&AU$4)),IF(OR(COUNTA($A6:$F6)>0,$G6<>""),$N6/12*IF($F6="",1,MAX(0,(EOMONTH(_xlpm.m,0)-MAX($F6,_xlpm.m)+1)/(EOMONTH(_xlpm.m,0)-_xlpm.m+1))),"")) | AV6: =_xlfn.LET(_xlpm.m,IF(ISNUMBER(AV$4),DATE(YEAR(AV$4),MONTH(AV$4),1),DATEVALUE("1-"&AV$4)),IF(OR(COUNTA($A6:$F6)>0,$G6<>""),$N6/12*IF($F6="",1,MAX(0,(EOMONTH(_xlpm.m,0)-MAX($F6,_xlpm.m)+1)/(EOMONTH(_xlpm.m,0)-_xlpm.m+1))),"")) | ... AZ6: =_xlfn.LET(_xlpm.m,IF(ISNUMBER(AZ$4),DATE(YEAR(AZ$4),MONTH(AZ$4),1),DATEVALUE("1-"&AZ$4)),IF(OR(COUNTA($A6:$F6)>0,$G6<>""),$N6/12*IF($F6="",1,MAX(0,(EOMONTH(_xlpm.m,0)-MAX($F6,_xlpm.m)+1)/(EOMONTH(_xlpm.m,0)-_xlpm.m+1))),"")) | BA6: =IF(COUNTA($A6:$H6)>0,SUM(AO6:AZ6),"")
