Workbook

Sheet Summary
B1: Essentials Operations
B3: Total
C4: 2026 | D4: 2027 | E4: 2028 | F4: 2029 | G4: 2027 vs. 2026 Variance | H4: 2027 vs. 2026 Variance %
B5: Compensation | C5: =C43+C81 -> 11677112 | D5: =D43+D81 -> 12353631 | E5: =E43+E81 -> 12353631 | F5: =F43+F81 -> 12353631 | G5: =D5-C5 -> 676519 | H5: =D5/C5-1 -> 0.057935472
B6: Bonus | C6: =C44+C82 -> 2316552 | D6: =D44+D82 -> 2450762.5 | E6: =E44+E82 -> 2450762.5 | F6: =F44+F82 -> 2450762.5 | G6: =D6-C6 -> 134210.53 | H6: =D6/C6-1 -> 0.057935472
B7: Essentials Bonus | C7: =C45+C83 -> 4466769.9 | D7: =D45+D83 -> 4466769.9 | E7: =E45+E83 -> 4466769.9 | F7: =F45+F83 -> 4466769.9 | G7: =D7-C7 -> 0 | H7: =D7/C7-1 -> 0
B8: Payroll Taxes | C8: =C46+C84 -> 1500352 | D8: =D46+D84 -> 1587275.6 | E8: =E46+E84 -> 1587275.6 | F8: =F46+F84 -> 1587275.6 | G8: =D8-C8 -> 86923.602 | H8: =D8/C8-1 -> 0.057935472
B9: Benefits | C9: =C47+C85 -> 1806053 | D9: =D47+D85 -> 1910687.5 | E9: =E47+E85 -> 1910687.5 | F9: =F47+F85 -> 1910687.5 | G9: =D9-C9 -> 104634.53 | H9: =D9/C9-1 -> 0.057935472
B10: Vacation | C10: =C48+C86 -> 127917 | D10: =D48+D86 -> 135327.93 | E10: =E48+E86 -> 135327.93 | F10: =F48+F86 -> 135327.93 | G10: =D10-C10 -> 7410.9318 | H10: =D10/C10-1 -> 0.057935472
B11: Other | C11: =C49+C87 -> 50 | D11: =D49+D87 -> 52.896774 | E11: =E49+E87 -> 52.896774 | F11: =F49+F87 -> 52.896774 | G11: =D11-C11 -> 2.8967736 | H11: =D11/C11-1 -> 0.057935472
B12: Contract Labor | C12: =C50+C88 -> 798527.16 | D12: =D50+D88 -> 798527.16 | E12: =E50+E88 -> 798527.16 | F12: =F50+F88 -> 798527.16 | G12: =D12-C12 -> 0 | H12: =D12/C12-1 -> 0
B13: LTIP Compensation | C13: =C51+C89 -> 1515941.8 | D13: =D51+D89 -> 1714335 | E13: =E51+E89 -> 1714335 | F13: =F51+F89 -> 1714335 | G13: =D13-C13 -> 198393.2 | H13: =D13/C13-1 -> 0.13087125
B14: Total Payroll | C14: =SUM(C5:C13) -> 24209275 | D14: =SUM(D5:D13) -> 25417370 | E14: =SUM(E5:E13) -> 25417370 | F14: =SUM(F5:F13) -> 25417370 | G14: =SUM(G5:G13) -> 1208094.7 | H14: =D14/C14-1 -> 0.049902143
B16: Professional Fees | C16: =C54+C92 -> 800690.01 | D16: =D54+D92 -> 800690.01 | E16: =E54+E92 -> 800690.01 | F16: =F54+F92 -> 800690.01 | G16: =D16-C16 -> 0 | H16: =IFERROR(D16/C16-1,0) -> 0
B17: Occupancy | C17: =C55+C93 -> 0 | D17: =D55+D93 -> 0 | E17: =E55+E93 -> 0 | F17: =F55+F93 -> 0 | G17: =D17-C17 -> 0 | H17: =IFERROR(D17/C17-1,0) -> 0
B18: Office Expenses | C18: =C56+C94 -> 9004.22 | D18: =D56+D94 -> 9004.22 | E18: =E56+E94 -> 9004.22 | F18: =F56+F94 -> 9004.22 | G18: =D18-C18 -> 0 | H18: =IFERROR(D18/C18-1,0) -> 0
B19: IT Costs | C19: =C57+C95 -> 49202.28 | D19: =D57+D95 -> 49202.28 | E19: =E57+E95 -> 49202.28 | F19: =F57+F95 -> 49202.28 | G19: =D19-C19 -> 0 | H19: =IFERROR(D19/C19-1,0) -> 0
B20: Marketing and Presentation | C20: =C58+C96 -> 36685.95 | D20: =D58+D96 -> 36685.95 | E20: =E58+E96 -> 36685.95 | F20: =F58+F96 -> 36685.95 | G20: =D20-C20 -> 0 | H20: =IFERROR(D20/C20-1,0) -> 0
B21: Travel and Entertainment | C21: =C59+C97 -> 1380796.7 | D21: =D59+D97 -> 1380796.7 | E21: =E59+E97 -> 1380796.7 | F21: =F59+F97 -> 1380796.7 | G21: =D21-C21 -> 0 | H21: =IFERROR(D21/C21-1,0) -> 0
B22: Employee events | C22: =C60+C98 -> 49427.32 | D22: =D60+D98 -> 49427.32 | E22: =E60+E98 -> 49427.32 | F22: =F60+F98 -> 49427.32 | G22: =D22-C22 -> 0 | H22: =IFERROR(D22/C22-1,0) -> 0
B23: Insurance Non Property | C23: =C61+C99 -> 0 | D23: =D61+D99 -> 0 | E23: =E61+E99 -> 0 | F23: =F61+F99 -> 0 | G23: =D23-C23 -> 0 | H23: =IFERROR(D23/C23-1,0) -> 0
B24: Licenses | C24: =C62+C100 -> 0 | D24: =D62+D100 -> 0 | E24: =E62+E100 -> 0 | F24: =F62+F100 -> 0 | G24: =D24-C24 -> 0 | H24: =IFERROR(D24/C24-1,0) -> 0
B25: Recruiting and Relocation | C25: =C63+C101 -> 40000.92 | D25: =D63+D101 -> 40000.92 | E25: =E63+E101 -> 40000.92 | F25: =F63+F101 -> 40000.92 | G25: =D25-C25 -> 0 | H25: =IFERROR(D25/C25-1,0) -> 0
B26: Seminars and Training | C26: =C64+C102 -> 39685.13 | D26: =D64+D102 -> 39685.13 | E26: =E64+E102 -> 39685.13 | F26: =F64+F102 -> 39685.13 | G26: =D26-C26 -> 0 | H26: =IFERROR(D26/C26-1,0) -> 0
B27: Shareholder Relations | C27: =C65+C103 -> 0 | D27: =D65+D103 -> 0 | E27: =E65+E103 -> 0 | F27: =F65+F103 -> 0 | G27: =D27-C27 -> 0 | H27: =IFERROR(D27/C27-1,0) -> 0
... B36: Allocated IT & Office Contra | C36: =C74+C112 -> 0 | D36: =D74+D112 -> 0 | E36: =E74+E112 -> 0 | F36: =F74+F112 -> 0 | G36: =D36-C36 -> 0 | H36: =IFERROR(D36/C36-1,0) -> 0
B37: Total Non-Payroll | C37: =SUM(C16:C36) -> 2405492.9 | D37: =SUM(D16:D36) -> 2405492.9 | E37: =SUM(E16:E36) -> 2405492.9 | F37: =SUM(F16:F36) -> 2405492.9 | G37: =SUM(G16:G36) -> 0 | H37: =IFERROR(D37/C37-1,0) -> 0
B39: Total | C39: =C14+C37 -> 26614768 | D39: =D14+D37 -> 27822862 | E39: =E14+E37 -> 27822862 | F39: =F14+F37 -> 27822862 | G39: =G14+G37 -> 1208094.7 | H39: =IFERROR(D39/C39-1,0) -> 0.045391893
B41: Baseline
C42: 2026 | D42: 2027 | E42: 2028 | F42: 2029 | G42: 2027 vs. 2026 Variance | H42: 2027 vs. 2026 Variance %
B43: Compensation | C43: =SUMIFS('Base - Payroll'!$E:$E,'Base - Payroll'!$A:$A,Summary!$B43) -> 11677112 | D43: =SUMIFS('Base - Payroll'!$G:$G,'Base - Payroll'!$A:$A,Summary!$B43) -> 12353631 | E43: =SUMIFS('Base - Payroll'!$H:$H,'Base - Payroll'!$A:$A,Summary!$B43) -> 12353631 | F43: =SUMIFS('Base - Payroll'!$I:$I,'Base - Payroll'!$A:$A,Summary!$B43) -> 12353631 | G43: =D43-C43 -> 676519 | H43: =IFERROR(D43/C43-1,0) -> 0.057935472
B44: Bonus | C44: =SUMIFS('Base - Payroll'!$E:$E,'Base - Payroll'!$A:$A,Summary!$B44) -> 2316552 | D44: =SUMIFS('Base - Payroll'!$G:$G,'Base - Payroll'!$A:$A,Summary!$B44) -> 2450762.5 | E44: =SUMIFS('Base - Payroll'!$H:$H,'Base - Payroll'!$A:$A,Summary!$B44) -> 2450762.5 | F44: =SUMIFS('Base - Payroll'!$I:$I,'Base - Payroll'!$A:$A,Summary!$B44) -> 2450762.5 | G44: =D44-C44 -> 134210.53 | H44: =IFERROR(D44/C44-1,0) -> 0.057935472
B45: Essentials Bonus | C45: =SUMIFS('Base - Non-Payroll'!$E:$E,'Base - Non-Payroll'!$A:$A,Summary!$B45) -> 4466769.9 | D45: ='Base - Non-Payroll'!H24 -> 4466769.9 | E45: ='Base - Non-Payroll'!J24 -> 4466769.9 | F45: ='Base - Non-Payroll'!L24 -> 4466769.9 | G45: =D45-C45 -> 0 | H45: =IFERROR(D45/C45-1,0) -> 0
B46: Payroll Taxes | C46: =SUMIFS('Base - Payroll'!$E:$E,'Base - Payroll'!$A:$A,Summary!$B46) -> 1500352 | D46: =SUMIFS('Base - Payroll'!$G:$G,'Base - Payroll'!$A:$A,Summary!$B46) -> 1587275.6 | E46: =SUMIFS('Base - Payroll'!$H:$H,'Base - Payroll'!$A:$A,Summary!$B46) -> 1587275.6 | F46: =SUMIFS('Base - Payroll'!$I:$I,'Base - Payroll'!$A:$A,Summary!$B46) -> 1587275.6 | G46: =D46-C46 -> 86923.602 | H46: =IFERROR(D46/C46-1,0) -> 0.057935472
B47: Benefits | C47: =SUMIFS('Base - Payroll'!$E:$E,'Base - Payroll'!$A:$A,Summary!$B47) -> 1806053 | D47: =SUMIFS('Base - Payroll'!$G:$G,'Base - Payroll'!$A:$A,Summary!$B47) -> 1910687.5 | E47: =SUMIFS('Base - Payroll'!$H:$H,'Base - Payroll'!$A:$A,Summary!$B47) -> 1910687.5 | F47: =SUMIFS('Base - Payroll'!$I:$I,'Base - Payroll'!$A:$A,Summary!$B47) -> 1910687.5 | G47: =D47-C47 -> 104634.53 | H47: =IFERROR(D47/C47-1,0) -> 0.057935472
B48: Vacation | C48: =SUMIFS('Base - Payroll'!$E:$E,'Base - Payroll'!$A:$A,Summary!$B48) -> 127917 | D48: =SUMIFS('Base - Payroll'!$G:$G,'Base - Payroll'!$A:$A,Summary!$B48) -> 135327.93 | E48: =SUMIFS('Base - Payroll'!$H:$H,'Base - Payroll'!$A:$A,Summary!$B48) -> 135327.93 | F48: =SUMIFS('Base - Payroll'!$I:$I,'Base - Payroll'!$A:$A,Summary!$B48) -> 135327.93 | G48: =D48-C48 -> 7410.9318 | H48: =IFERROR(D48/C48-1,0) -> 0.057935472
B49: Other | C49: =SUMIFS('Base - Payroll'!$E:$E,'Base - Payroll'!$A:$A,Summary!$B49) -> 50 | D49: =SUMIFS('Base - Payroll'!$G:$G,'Base - Payroll'!$A:$A,Summary!$B49) -> 52.896774 | E49: =SUMIFS('Base - Payroll'!$H:$H,'Base - Payroll'!$A:$A,Summary!$B49) -> 52.896774 | F49: =SUMIFS('Base - Payroll'!$I:$I,'Base - Payroll'!$A:$A,Summary!$B49) -> 52.896774 | G49: =D49-C49 -> 2.8967736 | H49: =IFERROR(D49/C49-1,0) -> 0.057935472
B50: Contract Labor | C50: =SUMIFS('Base - Non-Payroll'!$E:$E,'Base - Non-Payroll'!$A:$A,Summary!$B50) -> 798527.16 | D50: ='Base - Non-Payroll'!H25 -> 798527.16 | E50: ='Base - Non-Payroll'!J25 -> 798527.16 | F50: ='Base - Non-Payroll'!L25 -> 798527.16 | G50: =D50-C50 -> 0 | H50: =IFERROR(D50/C50-1,0) -> 0
B51: LTIP Compensation | C51: =SUMIFS('Base - Payroll'!$E:$E,'Base - Payroll'!$A:$A,Summary!$B51) -> 1515941.8 | D51: =SUMIFS('Base - Payroll'!$G:$G,'Base - Payroll'!$A:$A,Summary!$B51) -> 1714335 | E51: =SUMIFS('Base - Payroll'!$H:$H,'Base - Payroll'!$A:$A,Summary!$B51) -> 1714335 | F51: =SUMIFS('Base - Payroll'!$I:$I,'Base - Payroll'!$A:$A,Summary!$B51) -> 1714335 | G51: =D51-C51 -> 198393.2 | H51: =IFERROR(D51/C51-1,0) -> 0.13087125
B52: Baseline Payroll | C52: =SUM(C43:C51) -> 24209275 | D52: =SUM(D43:D51) -> 25417370 | E52: =SUM(E43:E51) -> 25417370 | F52: =SUM(F43:F51) -> 25417370 | G52: =SUM(G43:G51) -> 1208094.7 | H52: =IFERROR(D52/C52-1,0) -> 0.049902143
...

Sheet Investment Case Asks - Summary
A1: Investment Case Asks - Incremental Spend Input
A3: Payroll / Headcount Incremental Spend | T3: Incremental Spend Summary
A4: Job Title | B4: Job Level | C4: Role / Hire | D4: Location (City/Country) | E4: Key Job Responsibilities | F4: Hire Date | G4: Base Salary | H4: Bonus % | I4: Bonus | J4: Payroll Taxes | K4: Benefits | L4: Vacation | M4: Other | N4: 2027 Annualized Spend | O4: 2027 Incremental Spend | P4: 2028 Incremental Spend | Q4: 2029 Incremental Spend | R4: Notes / Rationale | T4: Spend Type | U4: 2027 | V4: 2028 | W4: 2029
A5: =IF(ISBLANK('Investment Case Asks - Monthly'!A5),"",'Investment Case Asks - Monthly'!A5) | B5: =IF(ISBLANK('Investment Case Asks - Monthly'!B5),"",'Investment Case Asks - Monthly'!B5) | C5: =IF(ISBLANK('Investment Case Asks - Monthly'!C5),"",'Investment Case Asks - Monthly'!C5) | D5: =IF(ISBLANK('Investment Case Asks - Monthly'!D5),"",'Investment Case Asks - Monthly'!D5) | E5: =IF(ISBLANK('Investment Case Asks - Monthly'!E5),"",'Investment Case Asks - Monthly'!E5) | F5: =IF(ISBLANK('Investment Case Asks - Monthly'!F5),"",'Investment Case Asks - Monthly'!F5) | G5: =IF(ISBLANK('Investment Case Asks - Monthly'!G5),"",'Investment Case Asks - Monthly'!G5) | H5: =IF(ISBLANK('Investment Case Asks - Monthly'!H5),"",'Investment Case Asks - Monthly'!H5) | ... N5: =IF(ISBLANK('Investment Case Asks - Monthly'!N5),"",'Investment Case Asks - Monthly'!N5) | O5: =IF(ISBLANK('Investment Case Asks - Monthly'!AA5),"",'Investment Case Asks - Monthly'!AA5) | P5: =IF(ISBLANK('Investment Case Asks - Monthly'!AN5),"",'Investment Case Asks - Monthly'!AN5) | Q5: =IF(ISBLANK('Investment Case Asks - Monthly'!BA5),"",'Investment Case Asks - Monthly'!BA5) | R5: =IF(ISBLANK('Investment Case Asks - Monthly'!BB5),"",'Investment Case Asks - Monthly'!BB5) | T5: Payroll / Headcount | U5: =O22 -> 0 | V5: =P22 -> 0 | W5: =Q22 -> 0
A6: =IF(ISBLANK('Investment Case Asks - Monthly'!A6),"",'Investment Case Asks - Monthly'!A6) | B6: =IF(ISBLANK('Investment Case Asks - Monthly'!B6),"",'Investment Case Asks - Monthly'!B6) | C6: =IF(ISBLANK('Investment Case Asks - Monthly'!C6),"",'Investment Case Asks - Monthly'!C6) | D6: =IF(ISBLANK('Investment Case Asks - Monthly'!D6),"",'Investment Case Asks - Monthly'!D6) | E6: =IF(ISBLANK('Investment Case Asks - Monthly'!E6),"",'Investment Case Asks - Monthly'!E6) | F6: =IF(ISBLANK('Investment Case Asks - Monthly'!F6),"",'Investment Case Asks - Monthly'!F6) | G6: =IF(ISBLANK('Investment Case Asks - Monthly'!G6),"",'Investment Case Asks - Monthly'!G6) | H6: =IF(ISBLANK('Investment Case Asks - Monthly'!H6),"",'Investment Case Asks - Monthly'!H6) | ... N6: =IF(ISBLANK('Investment Case Asks - Monthly'!N6),"",'Investment Case Asks - Monthly'!N6) | O6: =IF(ISBLANK('Investment Case Asks - Monthly'!AA6),"",'Investment Case Asks - Monthly'!AA6) | P6: =IF(ISBLANK('Investment Case Asks - Monthly'!AN6),"",'Investment Case Asks - Monthly'!AN6) | Q6: =IF(ISBLANK('Investment Case Asks - Monthly'!BA6),"",'Investment Case Asks - Monthly'!BA6) | R6: =IF(ISBLANK('Investment Case Asks - Monthly'!BB6),"",'Investment Case Asks - Monthly'!BB6) | T6: Non-Payroll | U6: =D44 -> 0 | V6: =E44 -> 0 | W6: =F44 -> 0
A7: =IF(ISBLANK('Investment Case Asks - Monthly'!A7),"",'Investment Case Asks - Monthly'!A7) | B7: =IF(ISBLANK('Investment Case Asks - Monthly'!B7),"",'Investment Case Asks - Monthly'!B7) | C7: =IF(ISBLANK('Investment Case Asks - Monthly'!C7),"",'Investment Case Asks - Monthly'!C7) | D7: =IF(ISBLANK('Investment Case Asks - Monthly'!D7),"",'Investment Case Asks - Monthly'!D7) | E7: =IF(ISBLANK('Investment Case Asks - Monthly'!E7),"",'Investment Case Asks - Monthly'!E7) | F7: =IF(ISBLANK('Investment Case Asks - Monthly'!F7),"",'Investment Case Asks - Monthly'!F7) | G7: =IF(ISBLANK('Investment Case Asks - Monthly'!G7),"",'Investment Case Asks - Monthly'!G7) | H7: =IF(ISBLANK('Investment Case Asks - Monthly'!H7),"",'Investment Case Asks - Monthly'!H7) | ... N7: =IF(ISBLANK('Investment Case Asks - Monthly'!N7),"",'Investment Case Asks - Monthly'!N7) | O7: =IF(ISBLANK('Investment Case Asks - Monthly'!AA7),"",'Investment Case Asks - Monthly'!AA7) | P7: =IF(ISBLANK('Investment Case Asks - Monthly'!AN7),"",'Investment Case Asks - Monthly'!AN7) | Q7: =IF(ISBLANK('Investment Case Asks - Monthly'!BA7),"",'Investment Case Asks - Monthly'!BA7) | R7: =IF(ISBLANK('Investment Case Asks - Monthly'!BB7),"",'Investment Case Asks - Monthly'!BB7) | T7: Total Incremental Spend | U7: =SUM(U5:U6) -> 0 | V7: =SUM(V5:V6) -> 0 | W7: =SUM(W5:W6) -> 0
A8: =IF(ISBLANK('Investment Case Asks - Monthly'!A8),"",'Investment Case Asks - Monthly'!A8) | B8: =IF(ISBLANK('Investment Case Asks - Monthly'!B8),"",'Investment Case Asks - Monthly'!B8) | C8: =IF(ISBLANK('Investment Case Asks - Monthly'!C8),"",'Investment Case Asks - Monthly'!C8) | D8: =IF(ISBLANK('Investment Case Asks - Monthly'!D8),"",'Investment Case Asks - Monthly'!D8) | E8: =IF(ISBLANK('Investment Case Asks - Monthly'!E8),"",'Investment Case Asks - Monthly'!E8) | F8: =IF(ISBLANK('Investment Case Asks - Monthly'!F8),"",'Investment Case Asks - Monthly'!F8) | G8: =IF(ISBLANK('Investment Case Asks - Monthly'!G8),"",'Investment Case Asks - Monthly'!G8) | H8: =IF(ISBLANK('Investment Case Asks - Monthly'!H8),"",'Investment Case Asks - Monthly'!H8) | ... N8: =IF(ISBLANK('Investment Case Asks - Monthly'!N8),"",'Investment Case Asks - Monthly'!N8) | O8: =IF(ISBLANK('Investment Case Asks - Monthly'!AA8),"",'Investment Case Asks - Monthly'!AA8) | P8: =IF(ISBLANK('Investment Case Asks - Monthly'!AN8),"",'Investment Case Asks - Monthly'!AN8) | Q8: =IF(ISBLANK('Investment Case Asks - Monthly'!BA8),"",'Investment Case Asks - Monthly'!BA8) | R8: =IF(ISBLANK('Investment Case Asks - Monthly'!BB8),"",'Investment Case Asks - Monthly'!BB8)
A9: =IF(ISBLANK('Investment Case Asks - Monthly'!A9),"",'Investment Case Asks - Monthly'!A9) | B9: =IF(ISBLANK('Investment Case Asks - Monthly'!B9),"",'Investment Case Asks - Monthly'!B9) | C9: =IF(ISBLANK('Investment Case Asks - Monthly'!C9),"",'Investment Case Asks - Monthly'!C9) | D9: =IF(ISBLANK('Investment Case Asks - Monthly'!D9),"",'Investment Case Asks - Monthly'!D9) | E9: =IF(ISBLANK('Investment Case Asks - Monthly'!E9),"",'Investment Case Asks - Monthly'!E9) | F9: =IF(ISBLANK('Investment Case Asks - Monthly'!F9),"",'Investment Case Asks - Monthly'!F9) | G9: =IF(ISBLANK('Investment Case Asks - Monthly'!G9),"",'Investment Case Asks - Monthly'!G9) | H9: =IF(ISBLANK('Investment Case Asks - Monthly'!H9),"",'Investment Case Asks - Monthly'!H9) | ... N9: =IF(ISBLANK('Investment Case Asks - Monthly'!N9),"",'Investment Case Asks - Monthly'!N9) | O9: =IF(ISBLANK('Investment Case Asks - Monthly'!AA9),"",'Investment Case Asks - Monthly'!AA9) | P9: =IF(ISBLANK('Investment Case Asks - Monthly'!AN9),"",'Investment Case Asks - Monthly'!AN9) | Q9: =IF(ISBLANK('Investment Case Asks - Monthly'!BA9),"",'Investment Case Asks - Monthly'!BA9) | R9: =IF(ISBLANK('Investment Case Asks - Monthly'!BB9),"",'Investment Case Asks - Monthly'!BB9)
A10: =IF(ISBLANK('Investment Case Asks - Monthly'!A10),"",'Investment Case Asks - Monthly'!A10) | B10: =IF(ISBLANK('Investment Case Asks - Monthly'!B10),"",'Investment Case Asks - Monthly'!B10) | C10: =IF(ISBLANK('Investment Case Asks - Monthly'!C10),"",'Investment Case Asks - Monthly'!C10) | D10: =IF(ISBLANK('Investment Case Asks - Monthly'!D10),"",'Investment Case Asks - Monthly'!D10) | E10: =IF(ISBLANK('Investment Case Asks - Monthly'!E10),"",'Investment Case Asks - Monthly'!E10) | F10: =IF(ISBLANK('Investment Case Asks - Monthly'!F10),"",'Investment Case Asks - Monthly'!F10) | G10: =IF(ISBLANK('Investment Case Asks - Monthly'!G10),"",'Investment Case Asks - Monthly'!G10) | H10: =IF(ISBLANK('Investment Case Asks - Monthly'!H10),"",'Investment Case Asks - Monthly'!H10) | ... N10: =IF(ISBLANK('Investment Case Asks - Monthly'!N10),"",'Investment Case Asks - Monthly'!N10) | O10: =IF(ISBLANK('Investment Case Asks - Monthly'!AA10),"",'Investment Case Asks - Monthly'!AA10) | P10: =IF(ISBLANK('Investment Case Asks - Monthly'!AN10),"",'Investment Case Asks - Monthly'!AN10) | Q10: =IF(ISBLANK('Investment Case Asks - Monthly'!BA10),"",'Investment Case Asks - Monthly'!BA10) | R10: =IF(ISBLANK('Investment Case Asks - Monthly'!BB10),"",'Investment Case Asks - Monthly'!BB10)
A11: =IF(ISBLANK('Investment Case Asks - Monthly'!A11),"",'Investment Case Asks - Monthly'!A11) | B11: =IF(ISBLANK('Investment Case Asks - Monthly'!B11),"",'Investment Case Asks - Monthly'!B11) | C11: =IF(ISBLANK('Investment Case Asks - Monthly'!C11),"",'Investment Case Asks - Monthly'!C11) | D11: =IF(ISBLANK('Investment Case Asks - Monthly'!D11),"",'Investment Case Asks - Monthly'!D11) | E11: =IF(ISBLANK('Investment Case Asks - Monthly'!E11),"",'Investment Case Asks - Monthly'!E11) | F11: =IF(ISBLANK('Investment Case Asks - Monthly'!F11),"",'Investment Case Asks - Monthly'!F11) | G11: =IF(ISBLANK('Investment Case Asks - Monthly'!G11),"",'Investment Case Asks - Monthly'!G11) | H11: =IF(ISBLANK('Investment Case Asks - Monthly'!H11),"",'Investment Case Asks - Monthly'!H11) | ... N11: =IF(ISBLANK('Investment Case Asks - Monthly'!N11),"",'Investment Case Asks - Monthly'!N11) | O11: =IF(ISBLANK('Investment Case Asks - Monthly'!AA11),"",'Investment Case Asks - Monthly'!AA11) | P11: =IF(ISBLANK('Investment Case Asks - Monthly'!AN11),"",'Investment Case Asks - Monthly'!AN11) | Q11: =IF(ISBLANK('Investment Case Asks - Monthly'!BA11),"",'Investment Case Asks - Monthly'!BA11) | R11: =IF(ISBLANK('Investment Case Asks - Monthly'!BB11),"",'Investment Case Asks - Monthly'!BB11)
A12: =IF(ISBLANK('Investment Case Asks - Monthly'!A12),"",'Investment Case Asks - Monthly'!A12) | B12: =IF(ISBLANK('Investment Case Asks - Monthly'!B12),"",'Investment Case Asks - Monthly'!B12) | C12: =IF(ISBLANK('Investment Case Asks - Monthly'!C12),"",'Investment Case Asks - Monthly'!C12) | D12: =IF(ISBLANK('Investment Case Asks - Monthly'!D12),"",'Investment Case Asks - Monthly'!D12) | E12: =IF(ISBLANK('Investment Case Asks - Monthly'!E12),"",'Investment Case Asks - Monthly'!E12) | F12: =IF(ISBLANK('Investment Case Asks - Monthly'!F12),"",'Investment Case Asks - Monthly'!F12) | G12: =IF(ISBLANK('Investment Case Asks - Monthly'!G12),"",'Investment Case Asks - Monthly'!G12) | H12: =IF(ISBLANK('Investment Case Asks - Monthly'!H12),"",'Investment Case Asks - Monthly'!H12) | ... N12: =IF(ISBLANK('Investment Case Asks - Monthly'!N12),"",'Investment Case Asks - Monthly'!N12) | O12: =IF(ISBLANK('Investment Case Asks - Monthly'!AA12),"",'Investment Case Asks - Monthly'!AA12) | P12: =IF(ISBLANK('Investment Case Asks - Monthly'!AN12),"",'Investment Case Asks - Monthly'!AN12) | Q12: =IF(ISBLANK('Investment Case Asks - Monthly'!BA12),"",'Investment Case Asks - Monthly'!BA12) | R12: =IF(ISBLANK('Investment Case Asks - Monthly'!BB12),"",'Investment Case Asks - Monthly'!BB12)
A13: =IF(ISBLANK('Investment Case Asks - Monthly'!A13),"",'Investment Case Asks - Monthly'!A13) | B13: =IF(ISBLANK('Investment Case Asks - Monthly'!B13),"",'Investment Case Asks - Monthly'!B13) | C13: =IF(ISBLANK('Investment Case Asks - Monthly'!C13),"",'Investment Case Asks - Monthly'!C13) | D13: =IF(ISBLANK('Investment Case Asks - Monthly'!D13),"",'Investment Case Asks - Monthly'!D13) | E13: =IF(ISBLANK('Investment Case Asks - Monthly'!E13),"",'Investment Case Asks - Monthly'!E13) | F13: =IF(ISBLANK('Investment Case Asks - Monthly'!F13),"",'Investment Case Asks - Monthly'!F13) | G13: =IF(ISBLANK('Investment Case Asks - Monthly'!G13),"",'Investment Case Asks - Monthly'!G13) | H13: =IF(ISBLANK('Investment Case Asks - Monthly'!H13),"",'Investment Case Asks - Monthly'!H13) | ... N13: =IF(ISBLANK('Investment Case Asks - Monthly'!N13),"",'Investment Case Asks - Monthly'!N13) | O13: =IF(ISBLANK('Investment Case Asks - Monthly'!AA13),"",'Investment Case Asks - Monthly'!AA13) | P13: =IF(ISBLANK('Investment Case Asks - Monthly'!AN13),"",'Investment Case Asks - Monthly'!AN13) | Q13: =IF(ISBLANK('Investment Case Asks - Monthly'!BA13),"",'Investment Case Asks - Monthly'!BA13) | R13: =IF(ISBLANK('Investment Case Asks - Monthly'!BB13),"",'Investment Case Asks - Monthly'!BB13)
A14: =IF(ISBLANK('Investment Case Asks - Monthly'!A14),"",'Investment Case Asks - Monthly'!A14) | B14: =IF(ISBLANK('Investment Case Asks - Monthly'!B14),"",'Investment Case Asks - Monthly'!B14) | C14: =IF(ISBLANK('Investment Case Asks - Monthly'!C14),"",'Investment Case Asks - Monthly'!C14) | D14: =IF(ISBLANK('Investment Case Asks - Monthly'!D14),"",'Investment Case Asks - Monthly'!D14) | E14: =IF(ISBLANK('Investment Case Asks - Monthly'!E14),"",'Investment Case Asks - Monthly'!E14) | F14: =IF(ISBLANK('Investment Case Asks - Monthly'!F14),"",'Investment Case Asks - Monthly'!F14) | G14: =IF(ISBLANK('Investment Case Asks - Monthly'!G14),"",'Investment Case Asks - Monthly'!G14) | H14: =IF(ISBLANK('Investment Case Asks - Monthly'!H14),"",'Investment Case Asks - Monthly'!H14) | ... N14: =IF(ISBLANK('Investment Case Asks - Monthly'!N14),"",'Investment Case Asks - Monthly'!N14) | O14: =IF(ISBLANK('Investment Case Asks - Monthly'!AA14),"",'Investment Case Asks - Monthly'!AA14) | P14: =IF(ISBLANK('Investment Case Asks - Monthly'!AN14),"",'Investment Case Asks - Monthly'!AN14) | Q14: =IF(ISBLANK('Investment Case Asks - Monthly'!BA14),"",'Investment Case Asks - Monthly'!BA14) | R14: =IF(ISBLANK('Investment Case Asks - Monthly'!BB14),"",'Investment Case Asks - Monthly'!BB14)
A15: =IF(ISBLANK('Investment Case Asks - Monthly'!A15),"",'Investment Case Asks - Monthly'!A15) | B15: =IF(ISBLANK('Investment Case Asks - Monthly'!B15),"",'Investment Case Asks - Monthly'!B15) | C15: =IF(ISBLANK('Investment Case Asks - Monthly'!C15),"",'Investment Case Asks - Monthly'!C15) | D15: =IF(ISBLANK('Investment Case Asks - Monthly'!D15),"",'Investment Case Asks - Monthly'!D15) | E15: =IF(ISBLANK('Investment Case Asks - Monthly'!E15),"",'Investment Case Asks - Monthly'!E15) | F15: =IF(ISBLANK('Investment Case Asks - Monthly'!F15),"",'Investment Case Asks - Monthly'!F15) | G15: =IF(ISBLANK('Investment Case Asks - Monthly'!G15),"",'Investment Case Asks - Monthly'!G15) | H15: =IF(ISBLANK('Investment Case Asks - Monthly'!H15),"",'Investment Case Asks - Monthly'!H15) | ... N15: =IF(ISBLANK('Investment Case Asks - Monthly'!N15),"",'Investment Case Asks - Monthly'!N15) | O15: =IF(ISBLANK('Investment Case Asks - Monthly'!AA15),"",'Investment Case Asks - Monthly'!AA15) | P15: =IF(ISBLANK('Investment Case Asks - Monthly'!AN15),"",'Investment Case Asks - Monthly'!AN15) | Q15: =IF(ISBLANK('Investment Case Asks - Monthly'!BA15),"",'Investment Case Asks - Monthly'!BA15) | R15: =IF(ISBLANK('Investment Case Asks - Monthly'!BB15),"",'Investment Case Asks - Monthly'!BB15)
A16: =IF(ISBLANK('Investment Case Asks - Monthly'!A16),"",'Investment Case Asks - Monthly'!A16) | B16: =IF(ISBLANK('Investment Case Asks - Monthly'!B16),"",'Investment Case Asks - Monthly'!B16) | C16: =IF(ISBLANK('Investment Case Asks - Monthly'!C16),"",'Investment Case Asks - Monthly'!C16) | D16: =IF(ISBLANK('Investment Case Asks - Monthly'!D16),"",'Investment Case Asks - Monthly'!D16) | E16: =IF(ISBLANK('Investment Case Asks - Monthly'!E16),"",'Investment Case Asks - Monthly'!E16) | F16: =IF(ISBLANK('Investment Case Asks - Monthly'!F16),"",'Investment Case Asks - Monthly'!F16) | G16: =IF(ISBLANK('Investment Case Asks - Monthly'!G16),"",'Investment Case Asks - Monthly'!G16) | H16: =IF(ISBLANK('Investment Case Asks - Monthly'!H16),"",'Investment Case Asks - Monthly'!H16) | ... N16: =IF(ISBLANK('Investment Case Asks - Monthly'!N16),"",'Investment Case Asks - Monthly'!N16) | O16: =IF(ISBLANK('Investment Case Asks - Monthly'!AA16),"",'Investment Case Asks - Monthly'!AA16) | P16: =IF(ISBLANK('Investment Case Asks - Monthly'!AN16),"",'Investment Case Asks - Monthly'!AN16) | Q16: =IF(ISBLANK('Investment Case Asks - Monthly'!BA16),"",'Investment Case Asks - Monthly'!BA16) | R16: =IF(ISBLANK('Investment Case Asks - Monthly'!BB16),"",'Investment Case Asks - Monthly'!BB16)
A17: =IF(ISBLANK('Investment Case Asks - Monthly'!A17),"",'Investment Case Asks - Monthly'!A17) | B17: =IF(ISBLANK('Investment Case Asks - Monthly'!B17),"",'Investment Case Asks - Monthly'!B17) | C17: =IF(ISBLANK('Investment Case Asks - Monthly'!C17),"",'Investment Case Asks - Monthly'!C17) | D17: =IF(ISBLANK('Investment Case Asks - Monthly'!D17),"",'Investment Case Asks - Monthly'!D17) | E17: =IF(ISBLANK('Investment Case Asks - Monthly'!E17),"",'Investment Case Asks - Monthly'!E17) | F17: =IF(ISBLANK('Investment Case Asks - Monthly'!F17),"",'Investment Case Asks - Monthly'!F17) | G17: =IF(ISBLANK('Investment Case Asks - Monthly'!G17),"",'Investment Case Asks - Monthly'!G17) | H17: =IF(ISBLANK('Investment Case Asks - Monthly'!H17),"",'Investment Case Asks - Monthly'!H17) | ... N17: =IF(ISBLANK('Investment Case Asks - Monthly'!N17),"",'Investment Case Asks - Monthly'!N17) | O17: =IF(ISBLANK('Investment Case Asks - Monthly'!AA17),"",'Investment Case Asks - Monthly'!AA17) | P17: =IF(ISBLANK('Investment Case Asks - Monthly'!AN17),"",'Investment Case Asks - Monthly'!AN17) | Q17: =IF(ISBLANK('Investment Case Asks - Monthly'!BA17),"",'Investment Case Asks - Monthly'!BA17) | R17: =IF(ISBLANK('Investment Case Asks - Monthly'!BB17),"",'Investment Case Asks - Monthly'!BB17)
A18: =IF(ISBLANK('Investment Case Asks - Monthly'!A18),"",'Investment Case Asks - Monthly'!A18) | B18: =IF(ISBLANK('Investment Case Asks - Monthly'!B18),"",'Investment Case Asks - Monthly'!B18) | C18: =IF(ISBLANK('Investment Case Asks - Monthly'!C18),"",'Investment Case Asks - Monthly'!C18) | D18: =IF(ISBLANK('Investment Case Asks - Monthly'!D18),"",'Investment Case Asks - Monthly'!D18) | E18: =IF(ISBLANK('Investment Case Asks - Monthly'!E18),"",'Investment Case Asks - Monthly'!E18) | F18: =IF(ISBLANK('Investment Case Asks - Monthly'!F18),"",'Investment Case Asks - Monthly'!F18) | G18: =IF(ISBLANK('Investment Case Asks - Monthly'!G18),"",'Investment Case Asks - Monthly'!G18) | H18: =IF(ISBLANK('Investment Case Asks - Monthly'!H18),"",'Investment Case Asks - Monthly'!H18) | ... N18: =IF(ISBLANK('Investment Case Asks - Monthly'!N18),"",'Investment Case Asks - Monthly'!N18) | O18: =IF(ISBLANK('Investment Case Asks - Monthly'!AA18),"",'Investment Case Asks - Monthly'!AA18) | P18: =IF(ISBLANK('Investment Case Asks - Monthly'!AN18),"",'Investment Case Asks - Monthly'!AN18) | Q18: =IF(ISBLANK('Investment Case Asks - Monthly'!BA18),"",'Investment Case Asks - Monthly'!BA18) | R18: =IF(ISBLANK('Investment Case Asks - Monthly'!BB18),"",'Investment Case Asks - Monthly'!BB18)
A19: =IF(ISBLANK('Investment Case Asks - Monthly'!A19),"",'Investment Case Asks - Monthly'!A19) | B19: =IF(ISBLANK('Investment Case Asks - Monthly'!B19),"",'Investment Case Asks - Monthly'!B19) | C19: =IF(ISBLANK('Investment Case Asks - Monthly'!C19),"",'Investment Case Asks - Monthly'!C19) | D19: =IF(ISBLANK('Investment Case Asks - Monthly'!D19),"",'Investment Case Asks - Monthly'!D19) | E19: =IF(ISBLANK('Investment Case Asks - Monthly'!E19),"",'Investment Case Asks - Monthly'!E19) | F19: =IF(ISBLANK('Investment Case Asks - Monthly'!F19),"",'Investment Case Asks - Monthly'!F19) | G19: =IF(ISBLANK('Investment Case Asks - Monthly'!G19),"",'Investment Case Asks - Monthly'!G19) | H19: =IF(ISBLANK('Investment Case Asks - Monthly'!H19),"",'Investment Case Asks - Monthly'!H19) | ... N19: =IF(ISBLANK('Investment Case Asks - Monthly'!N19),"",'Investment Case Asks - Monthly'!N19) | O19: =IF(ISBLANK('Investment Case Asks - Monthly'!AA19),"",'Investment Case Asks - Monthly'!AA19) | P19: =IF(ISBLANK('Investment Case Asks - Monthly'!AN19),"",'Investment Case Asks - Monthly'!AN19) | Q19: =IF(ISBLANK('Investment Case Asks - Monthly'!BA19),"",'Investment Case Asks - Monthly'!BA19) | R19: =IF(ISBLANK('Investment Case Asks - Monthly'!BB19),"",'Investment Case Asks - Monthly'!BB19)
A20: =IF(ISBLANK('Investment Case Asks - Monthly'!A20),"",'Investment Case Asks - Monthly'!A20) | B20: =IF(ISBLANK('Investment Case Asks - Monthly'!B20),"",'Investment Case Asks - Monthly'!B20) | C20: =IF(ISBLANK('Investment Case Asks - Monthly'!C20),"",'Investment Case Asks - Monthly'!C20) | D20: =IF(ISBLANK('Investment Case Asks - Monthly'!D20),"",'Investment Case Asks - Monthly'!D20) | E20: =IF(ISBLANK('Investment Case Asks - Monthly'!E20),"",'Investment Case Asks - Monthly'!E20) | F20: =IF(ISBLANK('Investment Case Asks - Monthly'!F20),"",'Investment Case Asks - Monthly'!F20) | G20: =IF(ISBLANK('Investment Case Asks - Monthly'!G20),"",'Investment Case Asks - Monthly'!G20) | H20: =IF(ISBLANK('Investment Case Asks - Monthly'!H20),"",'Investment Case Asks - Monthly'!H20) | ... N20: =IF(ISBLANK('Investment Case Asks - Monthly'!N20),"",'Investment Case Asks - Monthly'!N20) | O20: =IF(ISBLANK('Investment Case Asks - Monthly'!AA20),"",'Investment Case Asks - Monthly'!AA20) | P20: =IF(ISBLANK('Investment Case Asks - Monthly'!AN20),"",'Investment Case Asks - Monthly'!AN20) | Q20: =IF(ISBLANK('Investment Case Asks - Monthly'!BA20),"",'Investment Case Asks - Monthly'!BA20) | R20: =IF(ISBLANK('Investment Case Asks - Monthly'!BB20),"",'Investment Case Asks - Monthly'!BB20)
A22: Total Payroll / Headcount Incremental Spend | G22: =IF(ISBLANK('Investment Case Asks - Monthly'!G22),"",'Investment Case Asks - Monthly'!G22) -> 0 | I22: =IF(ISBLANK('Investment Case Asks - Monthly'!I22),"",'Investment Case Asks - Monthly'!I22) -> 0 | J22: =IF(ISBLANK('Investment Case Asks - Monthly'!J22),"",'Investment Case Asks - Monthly'!J22) -> 0 | K22: =IF(ISBLANK('Investment Case Asks - Monthly'!K22),"",'Investment Case Asks - Monthly'!K22) -> 0 | L22: =IF(ISBLANK('Investment Case Asks - Monthly'!L22),"",'Investment Case Asks - Monthly'!L22) -> 0 | M22: =IF(ISBLANK('Investment Case Asks - Monthly'!M22),"",'Investment Case Asks - Monthly'!M22) -> 0 | N22: =IF(ISBLANK('Investment Case Asks - Monthly'!N22),"",'Investment Case Asks - Monthly'!N22) -> 0 | O22: =IF(ISBLANK('Investment Case Asks - Monthly'!AA22),"",'Investment Case Asks - Monthly'!AA22) -> 0 | P22: =IF(ISBLANK('Investment Case Asks - Monthly'!AN22),"",'Investment Case Asks - Monthly'!AN22) -> 0 | Q22: =IF(ISBLANK('Investment Case Asks - Monthly'!BA22),"",'Investment Case Asks - Monthly'!BA22) -> 0
A26: Essentials Bonus / Contract Labor / Non-Payroll Incremental Spend
A27: Expense Description | B27: Type of Expense | C27: Vendor | D27: 2027 Incremental Spend | E27: 2028 Incremental Spend | F27: 2029 Incremental Spend | G27: Notes / Rationale
A28: =IF(ISBLANK('Investment Case Asks - Monthly'!A28),"",'Investment Case Asks - Monthly'!A28) | B28: =IF(ISBLANK('Investment Case Asks - Monthly'!B28),"",'Investment Case Asks - Monthly'!B28) | C28: =IF(ISBLANK('Investment Case Asks - Monthly'!C28),"",'Investment Case Asks - Monthly'!C28) | D28: =IF(ISBLANK('Investment Case Asks - Monthly'!Q28),"",'Investment Case Asks - Monthly'!Q28) | E28: =IF(ISBLANK('Investment Case Asks - Monthly'!AD28),"",'Investment Case Asks - Monthly'!AD28) | F28: =IF(ISBLANK('Investment Case Asks - Monthly'!AQ28),"",'Investment Case Asks - Monthly'!AQ28) | G28: =IF(ISBLANK('Investment Case Asks - Monthly'!AR28),"",'Investment Case Asks - Monthly'!AR28)
A29: =IF(ISBLANK('Investment Case Asks - Monthly'!A29),"",'Investment Case Asks - Monthly'!A29) | B29: =IF(ISBLANK('Investment Case Asks - Monthly'!B29),"",'Investment Case Asks - Monthly'!B29) | C29: =IF(ISBLANK('Investment Case Asks - Monthly'!C29),"",'Investment Case Asks - Monthly'!C29) | D29: =IF(ISBLANK('Investment Case Asks - Monthly'!Q29),"",'Investment Case Asks - Monthly'!Q29) | E29: =IF(ISBLANK('Investment Case Asks - Monthly'!AD29),"",'Investment Case Asks - Monthly'!AD29) | F29: =IF(ISBLANK('Investment Case Asks - Monthly'!AQ29),"",'Investment Case Asks - Monthly'!AQ29) | G29: =IF(ISBLANK('Investment Case Asks - Monthly'!AR29),"",'Investment Case Asks - Monthly'!AR29)
A30: =IF(ISBLANK('Investment Case Asks - Monthly'!A30),"",'Investment Case Asks - Monthly'!A30) | B30: =IF(ISBLANK('Investment Case Asks - Monthly'!B30),"",'Investment Case Asks - Monthly'!B30) | C30: =IF(ISBLANK('Investment Case Asks - Monthly'!C30),"",'Investment Case Asks - Monthly'!C30) | D30: =IF(ISBLANK('Investment Case Asks - Monthly'!Q30),"",'Investment Case Asks - Monthly'!Q30) | E30: =IF(ISBLANK('Investment Case Asks - Monthly'!AD30),"",'Investment Case Asks - Monthly'!AD30) | F30: =IF(ISBLANK('Investment Case Asks - Monthly'!AQ30),"",'Investment Case Asks - Monthly'!AQ30) | G30: =IF(ISBLANK('Investment Case Asks - Monthly'!AR30),"",'Investment Case Asks - Monthly'!AR30)
A31: =IF(ISBLANK('Investment Case Asks - Monthly'!A31),"",'Investment Case Asks - Monthly'!A31) | B31: =IF(ISBLANK('Investment Case Asks - Monthly'!B31),"",'Investment Case Asks - Monthly'!B31) | C31: =IF(ISBLANK('Investment Case Asks - Monthly'!C31),"",'Investment Case Asks - Monthly'!C31) | D31: =IF(ISBLANK('Investment Case Asks - Monthly'!Q31),"",'Investment Case Asks - Monthly'!Q31) | E31: =IF(ISBLANK('Investment Case Asks - Monthly'!AD31),"",'Investment Case Asks - Monthly'!AD31) | F31: =IF(ISBLANK('Investment Case Asks - Monthly'!AQ31),"",'Investment Case Asks - Monthly'!AQ31) | G31: =IF(ISBLANK('Investment Case Asks - Monthly'!AR31),"",'Investment Case Asks - Monthly'!AR31)
A32: =IF(ISBLANK('Investment Case Asks - Monthly'!A32),"",'Investment Case Asks - Monthly'!A32) | B32: =IF(ISBLANK('Investment Case Asks - Monthly'!B32),"",'Investment Case Asks - Monthly'!B32) | C32: =IF(ISBLANK('Investment Case Asks - Monthly'!C32),"",'Investment Case Asks - Monthly'!C32) | D32: =IF(ISBLANK('Investment Case Asks - Monthly'!Q32),"",'Investment Case Asks - Monthly'!Q32) | E32: =IF(ISBLANK('Investment Case Asks - Monthly'!AD32),"",'Investment Case Asks - Monthly'!AD32) | F32: =IF(ISBLANK('Investment Case Asks - Monthly'!AQ32),"",'Investment Case Asks - Monthly'!AQ32) | G32: =IF(ISBLANK('Investment Case Asks - Monthly'!AR32),"",'Investment Case Asks - Monthly'!AR32)
A33: =IF(ISBLANK('Investment Case Asks - Monthly'!A33),"",'Investment Case Asks - Monthly'!A33) | B33: =IF(ISBLANK('Investment Case Asks - Monthly'!B33),"",'Investment Case Asks - Monthly'!B33) | C33: =IF(ISBLANK('Investment Case Asks - Monthly'!C33),"",'Investment Case Asks - Monthly'!C33) | D33: =IF(ISBLANK('Investment Case Asks - Monthly'!Q33),"",'Investment Case Asks - Monthly'!Q33) | E33: =IF(ISBLANK('Investment Case Asks - Monthly'!AD33),"",'Investment Case Asks - Monthly'!AD33) | F33: =IF(ISBLANK('Investment Case Asks - Monthly'!AQ33),"",'Investment Case Asks - Monthly'!AQ33) | G33: =IF(ISBLANK('Investment Case Asks - Monthly'!AR33),"",'Investment Case Asks - Monthly'!AR33)
A34: =IF(ISBLANK('Investment Case Asks - Monthly'!A34),"",'Investment Case Asks - Monthly'!A34) | B34: =IF(ISBLANK('Investment Case Asks - Monthly'!B34),"",'Investment Case Asks - Monthly'!B34) | C34: =IF(ISBLANK('Investment Case Asks - Monthly'!C34),"",'Investment Case Asks - Monthly'!C34) | D34: =IF(ISBLANK('Investment Case Asks - Monthly'!Q34),"",'Investment Case Asks - Monthly'!Q34) | E34: =IF(ISBLANK('Investment Case Asks - Monthly'!AD34),"",'Investment Case Asks - Monthly'!AD34) | F34: =IF(ISBLANK('Investment Case Asks - Monthly'!AQ34),"",'Investment Case Asks - Monthly'!AQ34) | G34: =IF(ISBLANK('Investment Case Asks - Monthly'!AR34),"",'Investment Case Asks - Monthly'!AR34)
A35: =IF(ISBLANK('Investment Case Asks - Monthly'!A35),"",'Investment Case Asks - Monthly'!A35) | B35: =IF(ISBLANK('Investment Case Asks - Monthly'!B35),"",'Investment Case Asks - Monthly'!B35) | C35: =IF(ISBLANK('Investment Case Asks - Monthly'!C35),"",'Investment Case Asks - Monthly'!C35) | D35: =IF(ISBLANK('Investment Case Asks - Monthly'!Q35),"",'Investment Case Asks - Monthly'!Q35) | E35: =IF(ISBLANK('Investment Case Asks - Monthly'!AD35),"",'Investment Case Asks - Monthly'!AD35) | F35: =IF(ISBLANK('Investment Case Asks - Monthly'!AQ35),"",'Investment Case Asks - Monthly'!AQ35) | G35: =IF(ISBLANK('Investment Case Asks - Monthly'!AR35),"",'Investment Case Asks - Monthly'!AR35)
A36: =IF(ISBLANK('Investment Case Asks - Monthly'!A36),"",'Investment Case Asks - Monthly'!A36) | B36: =IF(ISBLANK('Investment Case Asks - Monthly'!B36),"",'Investment Case Asks - Monthly'!B36) | C36: =IF(ISBLANK('Investment Case Asks - Monthly'!C36),"",'Investment Case Asks - Monthly'!C36) | D36: =IF(ISBLANK('Investment Case Asks - Monthly'!Q36),"",'Investment Case Asks - Monthly'!Q36) | E36: =IF(ISBLANK('Investment Case Asks - Monthly'!AD36),"",'Investment Case Asks - Monthly'!AD36) | F36: =IF(ISBLANK('Investment Case Asks - Monthly'!AQ36),"",'Investment Case Asks - Monthly'!AQ36) | G36: =IF(ISBLANK('Investment Case Asks - Monthly'!AR36),"",'Investment Case Asks - Monthly'!AR36)
A37: =IF(ISBLANK('Investment Case Asks - Monthly'!A37),"",'Investment Case Asks - Monthly'!A37) | B37: =IF(ISBLANK('Investment Case Asks - Monthly'!B37),"",'Investment Case Asks - Monthly'!B37) | C37: =IF(ISBLANK('Investment Case Asks - Monthly'!C37),"",'Investment Case Asks - Monthly'!C37) | D37: =IF(ISBLANK('Investment Case Asks - Monthly'!Q37),"",'Investment Case Asks - Monthly'!Q37) | E37: =IF(ISBLANK('Investment Case Asks - Monthly'!AD37),"",'Investment Case Asks - Monthly'!AD37) | F37: =IF(ISBLANK('Investment Case Asks - Monthly'!AQ37),"",'Investment Case Asks - Monthly'!AQ37) | G37: =IF(ISBLANK('Investment Case Asks - Monthly'!AR37),"",'Investment Case Asks - Monthly'!AR37)
A38: =IF(ISBLANK('Investment Case Asks - Monthly'!A38),"",'Investment Case Asks - Monthly'!A38) | B38: =IF(ISBLANK('Investment Case Asks - Monthly'!B38),"",'Investment Case Asks - Monthly'!B38) | C38: =IF(ISBLANK('Investment Case Asks - Monthly'!C38),"",'Investment Case Asks - Monthly'!C38) | D38: =IF(ISBLANK('Investment Case Asks - Monthly'!Q38),"",'Investment Case Asks - Monthly'!Q38) | E38: =IF(ISBLANK('Investment Case Asks - Monthly'!AD38),"",'Investment Case Asks - Monthly'!AD38) | F38: =IF(ISBLANK('Investment Case Asks - Monthly'!AQ38),"",'Investment Case Asks - Monthly'!AQ38) | G38: =IF(ISBLANK('Investment Case Asks - Monthly'!AR38),"",'Investment Case Asks - Monthly'!AR38)
A39: =IF(ISBLANK('Investment Case Asks - Monthly'!A39),"",'Investment Case Asks - Monthly'!A39) | B39: =IF(ISBLANK('Investment Case Asks - Monthly'!B39),"",'Investment Case Asks - Monthly'!B39) | C39: =IF(ISBLANK('Investment Case Asks - Monthly'!C39),"",'Investment Case Asks - Monthly'!C39) | D39: =IF(ISBLANK('Investment Case Asks - Monthly'!Q39),"",'Investment Case Asks - Monthly'!Q39) | E39: =IF(ISBLANK('Investment Case Asks - Monthly'!AD39),"",'Investment Case Asks - Monthly'!AD39) | F39: =IF(ISBLANK('Investment Case Asks - Monthly'!AQ39),"",'Investment Case Asks - Monthly'!AQ39) | G39: =IF(ISBLANK('Investment Case Asks - Monthly'!AR39),"",'Investment Case Asks - Monthly'!AR39)
... A42: =IF(ISBLANK('Investment Case Asks - Monthly'!A42),"",'Investment Case Asks - Monthly'!A42) | B42: =IF(ISBLANK('Investment Case Asks - Monthly'!B42),"",'Investment Case Asks - Monthly'!B42) | C42: =IF(ISBLANK('Investment Case Asks - Monthly'!C42),"",'Investment Case Asks - Monthly'!C42) | D42: =IF(ISBLANK('Investment Case Asks - Monthly'!Q42),"",'Investment Case Asks - Monthly'!Q42) | E42: =IF(ISBLANK('Investment Case Asks - Monthly'!AD42),"",'Investment Case Asks - Monthly'!AD42) | F42: =IF(ISBLANK('Investment Case Asks - Monthly'!AQ42),"",'Investment Case Asks - Monthly'!AQ42) | G42: =IF(ISBLANK('Investment Case Asks - Monthly'!AR42),"",'Investment Case Asks - Monthly'!AR42)
A44: Total Essentials Bonus / Contract Labor / Non-Payroll Incremental Spend | D44: =SUM(D28:D42) -> 0 | E44: =SUM(E28:E42) -> 0 | F44: =SUM(F28:F42) -> 0

Sheet Investment Case Asks - Monthly
A1: Investment Case Asks - Incremental Spend Input
A3: Payroll / Headcount Incremental Spend
A4: Job Title | B4: Job Level | C4: Role / Hire | D4: Location (City/Country) | E4: Key Job Responsibilities | F4: Hire Date | G4: Base Salary | H4: Bonus % | I4: Bonus | J4: Payroll Taxes | K4: Benefits | L4: Vacation | M4: Other | N4: Annualized Spend | O4: Jan-27 | P4: Feb-27 | Q4: Mar-27 | R4: Apr-27 | S4: May-27 | T4: Jun-27 | U4: Jul-27 | V4: Aug-27 | W4: Sep-27 | X4: Oct-27 | Y4: Nov-27 | Z4: Dec-27 | AA4: 2027 Incremental Spend | AB4: Jan-28 | AC4: Feb-28 | AD4: Mar-28 | AE4: Apr-28 | AF4: May-28 | AG4: Jun-28 | AH4: Jul-28 | AI4: Aug-28 | AJ4: Sep-28 | AK4: Oct-28 | AL4: Nov-28 | AM4: Dec-28 | AN4: 2028 Incremental Spend | AO4: Jan-29 | AP4: Feb-29 | AQ4: Mar-29 | AR4: Apr-29 | AS4: May-29 | AT4: Jun-29 | AU4: Jul-29 | AV4: Aug-29 | AW4: Sep-29 | AX4: Oct-29 | AY4: Nov-29 | AZ4: Dec-29 | BA4: 2029 Incremental Spend | BB4: Notes / Rationale
I5: =IF(OR(COUNTA(tblPayrollIncrementalSpend2[[#This Row],[Job Title]:[Hire Date]])>0,AND(ROW()=ROW(G5),tblPayrollIncrementalSpend2[[#This Row],[Base Salary]]<>"")),N(tblPayrollIncrementalSpend2[[#This Row],[Base Salary]])*N(tblPayrollIncrementalSpend2[[#This Row],[Bonus %]]),"") | J5: =IF(OR(COUNTA(tblPayrollIncrementalSpend2[[#This Row],[Job Title]:[Hire Date]])>0,AND(ROW()=ROW(G5),tblPayrollIncrementalSpend2[[#This Row],[Base Salary]]<>"")),N(tblPayrollIncrementalSpend2[[#This Row],[Base Salary]])*'Base - Payroll'!$E$12,"") | K5: =IF(OR(COUNTA(tblPayrollIncrementalSpend2[[#This Row],[Job Title]:[Hire Date]])>0,AND(ROW()=ROW(G5),tblPayrollIncrementalSpend2[[#This Row],[Base Salary]]<>"")),N(tblPayrollIncrementalSpend2[[#This Row],[Base Salary]])*'Base - Payroll'!$E$13,"") | L5: =IF(OR(COUNTA(tblPayrollIncrementalSpend2[[#This Row],[Job Title]:[Hire Date]])>0,AND(ROW()=ROW(G5),tblPayrollIncrementalSpend2[[#This Row],[Base Salary]]<>"")),N(tblPayrollIncrementalSpend2[[#This Row],[Base Salary]])*'Base - Payroll'!$E$15,"") | M5: =IF(OR(COUNTA(tblPayrollIncrementalSpend2[[#This Row],[Job Title]:[Hire Date]])>0,AND(ROW()=ROW(G5),tblPayrollIncrementalSpend2[[#This Row],[Base Salary]]<>"")),N(tblPayrollIncrementalSpend2[[#This Row],[Base Salary]])*'Base - Payroll'!$E$16,"") | N5: =IF(OR(COUNTA(tblPayrollIncrementalSpend2[[#This Row],[Job Title]:[Hire Date]])>0,AND(ROW()=ROW(G5),tblPayrollIncrementalSpend2[[#This Row],[Base Salary]]<>"")),N(tblPayrollIncrementalSpend2[[#This Row],[Base Salary]])+SUM(tblPayrollIncrementalSpend2[[#This Row],[Bonus]:[Other]]),"") | O5: =_xlfn.LET(_xlpm.m,IF(ISNUMBER(O$4),DATE(YEAR(O$4),MONTH(O$4),1),DATEVALUE("1-"&O$4)),IF(OR(COUNTA($A5:$F5)>0,$G5<>""),$N5/12*IF($F5="",1,MAX(0,(EOMONTH(_xlpm.m,0)-MAX($F5,_xlpm.m)+1)/(EOMONTH(_xlpm.m,0)-_xlpm.m+1))),"")) | P5: =_xlfn.LET(_xlpm.m,IF(ISNUMBER(P$4),DATE(YEAR(P$4),MONTH(P$4),1),DATEVALUE("1-"&P$4)),IF(OR(COUNTA($A5:$F5)>0,$G5<>""),$N5/12*IF($F5="",1,MAX(0,(EOMONTH(_xlpm.m,0)-MAX($F5,_xlpm.m)+1)/(EOMONTH(_xlpm.m,0)-_xlpm.m+1))),"")) | Q5: =_xlfn.LET(_xlpm.m,IF(ISNUMBER(Q$4),DATE(YEAR(Q$4),MONTH(Q$4),1),DATEVALUE("1-"&Q$4)),IF(OR(COUNTA($A5:$F5)>0,$G5<>""),$N5/12*IF($F5="",1,MAX(0,(EOMONTH(_xlpm.m,0)-MAX($F5,_xlpm.m)+1)/(EOMONTH(_xlpm.m,0)-_xlpm.m+1))),"")) | R5: =_xlfn.LET(_xlpm.m,IF(ISNUMBER(R$4),DATE(YEAR(R$4),MONTH(R$4),1),DATEVALUE("1-"&R$4)),IF(OR(COUNTA($A5:$F5)>0,$G5<>""),$N5/12*IF($F5="",1,MAX(0,(EOMONTH(_xlpm.m,0)-MAX($F5,_xlpm.m)+1)/(EOMONTH(_xlpm.m,0)-_xlpm.m+1))),"")) | S5: =_xlfn.LET(_xlpm.m,IF(ISNUMBER(S$4),DATE(YEAR(S$4),MONTH(S$4),1),DATEVALUE("1-"&S$4)),IF(OR(COUNTA($A5:$F5)>0,$G5<>""),$N5/12*IF($F5="",1,MAX(0,(EOMONTH(_xlpm.m,0)-MAX($F5,_xlpm.m)+1)/(EOMONTH(_xlpm.m,0)-_xlpm.m+1))),"")) | T5: =_xlfn.LET(_xlpm.m,IF(ISNUMBER(T$4),DATE(YEAR(T$4),MONTH(T$4),1),DATEVALUE("1-"&T$4)),IF(OR(COUNTA($A5:$F5)>0,$G5<>""),$N5/12*IF($F5="",1,MAX(0,(EOMONTH(_xlpm.m,0)-MAX($F5,_xlpm.m)+1)/(EOMONTH(_xlpm.m,0)-_xlpm.m+1))),"")) | U5: =_xlfn.LET(_xlpm.m,IF(ISNUMBER(U$4),DATE(YEAR(U$4),MONTH(U$4),1),DATEVALUE("1-"&U$4)),IF(OR(COUNTA($A5:$F5)>0,$G5<>""),$N5/12*IF($F5="",1,MAX(0,(EOMONTH(_xlpm.m,0)-MAX($F5,_xlpm.m)+1)/(EOMONTH(_xlpm.m,0)-_xlpm.m+1))),"")) | V5: =_xlfn.LET(_xlpm.m,IF(ISNUMBER(V$4),DATE(YEAR(V$4),MONTH(V$4),1),DATEVALUE("1-"&V$4)),IF(OR(COUNTA($A5:$F5)>0,$G5<>""),$N5/12*IF($F5="",1,MAX(0,(EOMONTH(_xlpm.m,0)-MAX($F5,_xlpm.m)+1)/(EOMONTH(_xlpm.m,0)-_xlpm.m+1))),"")) | ... Z5: =_xlfn.LET(_xlpm.m,IF(ISNUMBER(Z$4),DATE(YEAR(Z$4),MONTH(Z$4),1),DATEVALUE("1-"&Z$4)),IF(OR(COUNTA($A5:$F5)>0,$G5<>""),$N5/12*IF($F5="",1,MAX(0,(EOMONTH(_xlpm.m,0)-MAX($F5,_xlpm.m)+1)/(EOMONTH(_xlpm.m,0)-_xlpm.m+1))),"")) | AA5: =IF(OR(COUNTA($A5:$F5)>0,$G5<>""),SUM(O5:Z5),"") | AB5: =_xlfn.LET(_xlpm.m,IF(ISNUMBER(AB$4),DATE(YEAR(AB$4),MONTH(AB$4),1),DATEVALUE("1-"&AB$4)),IF(OR(COUNTA($A5:$F5)>0,$G5<>""),$N5/12*IF($F5="",1,MAX(0,(EOMONTH(_xlpm.m,0)-MAX($F5,_xlpm.m)+1)/(EOMONTH(_xlpm.m,0)-_xlpm.m+1))),"")) | AC5: =_xlfn.LET(_xlpm.m,IF(ISNUMBER(AC$4),DATE(YEAR(AC$4),MONTH(AC$4),1),DATEVALUE("1-"&AC$4)),IF(OR(COUNTA($A5:$F5)>0,$G5<>""),$N5/12*IF($F5="",1,MAX(0,(EOMONTH(_xlpm.m,0)-MAX($F5,_xlpm.m)+1)/(EOMONTH(_xlpm.m,0)-_xlpm.m+1))),"")) | AD5: =_xlfn.LET(_xlpm.m,IF(ISNUMBER(AD$4),DATE(YEAR(AD$4),MONTH(AD$4),1),DATEVALUE("1-"&AD$4)),IF(OR(COUNTA($A5:$F5)>0,$G5<>""),$N5/12*IF($F5="",1,MAX(0,(EOMONTH(_xlpm.m,0)-MAX($F5,_xlpm.m)+1)/(EOMONTH(_xlpm.m,0)-_xlpm.m+1))),"")) | AE5: =_xlfn.LET(_xlpm.m,IF(ISNUMBER(AE$4),DATE(YEAR(AE$4),MONTH(AE$4),1),DATEVALUE("1-"&AE$4)),IF(OR(COUNTA($A5:$F5)>0,$G5<>""),$N5/12*IF($F5="",1,MAX(0,(EOMONTH(_xlpm.m,0)-MAX($F5,_xlpm.m)+1)/(EOMONTH(_xlpm.m,0)-_xlpm.m+1))),"")) | AF5: =_xlfn.LET(_xlpm.m,IF(ISNUMBER(AF$4),DATE(YEAR(AF$4),MONTH(AF$4),1),DATEVALUE("1-"&AF$4)),IF(OR(COUNTA($A5:$F5)>0,$G5<>""),$N5/12*IF($F5="",1,MAX(0,(EOMONTH(_xlpm.m,0)-MAX($F5,_xlpm.m)+1)/(EOMONTH(_xlpm.m,0)-_xlpm.m+1))),"")) | AG5: =_xlfn.LET(_xlpm.m,IF(ISNUMBER(AG$4),DATE(YEAR(AG$4),MONTH(AG$4),1),DATEVALUE("1-"&AG$4)),IF(OR(COUNTA($A5:$F5)>0,$G5<>""),$N5/12*IF($F5="",1,MAX(0,(EOMONTH(_xlpm.m,0)-MAX($F5,_xlpm.m)+1)/(EOMONTH(_xlpm.m,0)-_xlpm.m+1))),"")) | AH5: =_xlfn.LET(_xlpm.m,IF(ISNUMBER(AH$4),DATE(YEAR(AH$4),MONTH(AH$4),1),DATEVALUE("1-"&AH$4)),IF(OR(COUNTA($A5:$F5)>0,$G5<>""),$N5/12*IF($F5="",1,MAX(0,(EOMONTH(_xlpm.m,0)-MAX($F5,_xlpm.m)+1)/(EOMONTH(_xlpm.m,0)-_xlpm.m+1))),"")) | AI5: =_xlfn.LET(_xlpm.m,IF(ISNUMBER(AI$4),DATE(YEAR(AI$4),MONTH(AI$4),1),DATEVALUE("1-"&AI$4)),IF(OR(COUNTA($A5:$F5)>0,$G5<>""),$N5/12*IF($F5="",1,MAX(0,(EOMONTH(_xlpm.m,0)-MAX($F5,_xlpm.m)+1)/(EOMONTH(_xlpm.m,0)-_xlpm.m+1))),"")) | ... AM5: =_xlfn.LET(_xlpm.m,IF(ISNUMBER(AM$4),DATE(YEAR(AM$4),MONTH(AM$4),1),DATEVALUE("1-"&AM$4)),IF(OR(COUNTA($A5:$F5)>0,$G5<>""),$N5/12*IF($F5="",1,MAX(0,(EOMONTH(_xlpm.m,0)-MAX($F5,_xlpm.m)+1)/(EOMONTH(_xlpm.m,0)-_xlpm.m+1))),"")) | AN5: =IF(OR(COUNTA($A5:$F5)>0,$G5<>""),SUM(AB5:AM5),"") | AO5: =_xlfn.LET(_xlpm.m,IF(ISNUMBER(AO$4),DATE(YEAR(AO$4),MONTH(AO$4),1),DATEVALUE("1-"&AO$4)),IF(OR(COUNTA($A5:$F5)>0,$G5<>""),$N5/12*IF($F5="",1,MAX(0,(EOMONTH(_xlpm.m,0)-MAX($F5,_xlpm.m)+1)/(EOMONTH(_xlpm.m,0)-_xlpm.m+1))),"")) | AP5: =_xlfn.LET(_xlpm.m,IF(ISNUMBER(AP$4),DATE(YEAR(AP$4),MONTH(AP$4),1),DATEVALUE("1-"&AP$4)),IF(OR(COUNTA($A5:$F5)>0,$G5<>""),$N5/12*IF($F5="",1,MAX(0,(EOMONTH(_xlpm.m,0)-MAX($F5,_xlpm.m)+1)/(EOMONTH(_xlpm.m,0)-_xlpm.m+1))),"")) | AQ5: =_xlfn.LET(_xlpm.m,IF(ISNUMBER(AQ$4),DATE(YEAR(AQ$4),MONTH(AQ$4),1),DATEVALUE("1-"&AQ$4)),IF(OR(COUNTA($A5:$F5)>0,$G5<>""),$N5/12*IF($F5="",1,MAX(0,(EOMONTH(_xlpm.m,0)-MAX($F5,_xlpm.m)+1)/(EOMONTH(_xlpm.m,0)-_xlpm.m+1))),"")) | AR5: =_xlfn.LET(_xlpm.m,IF(ISNUMBER(AR$4),DATE(YEAR(AR$4),MONTH(AR$4),1),DATEVALUE("1-"&AR$4)),IF(OR(COUNTA($A5:$F5)>0,$G5<>""),$N5/12*IF($F5="",1,MAX(0,(EOMONTH(_xlpm.m,0)-MAX($F5,_xlpm.m)+1)/(EOMONTH(_xlpm.m,0)-_xlpm.m+1))),"")) | AS5: =_xlfn.LET(_xlpm.m,IF(ISNUMBER(AS$4),DATE(YEAR(AS$4),MONTH(AS$4),1),DATEVALUE("1-"&AS$4)),IF(OR(COUNTA($A5:$F5)>0,$G5<>""),$N5/12*IF($F5="",1,MAX(0,(EOMONTH(_xlpm.m,0)-MAX($F5,_xlpm.m)+1)/(EOMONTH(_xlpm.m,0)-_xlpm.m+1))),"")) | AT5: =_xlfn.LET(_xlpm.m,IF(ISNUMBER(AT$4),DATE(YEAR(AT$4),MONTH(AT$4),1),DATEVALUE("1-"&AT$4)),IF(OR(COUNTA($A5:$F5)>0,$G5<>""),$N5/12*IF($F5="",1,MAX(0,(EOMONTH(_xlpm.m,0)-MAX($F5,_xlpm.m)+1)/(EOMONTH(_xlpm.m,0)-_xlpm.m+1))),"")) | AU5: =_xlfn.LET(_xlpm.m,IF(ISNUMBER(AU$4),DATE(YEAR(AU$4),MONTH(AU$4),1),DATEVALUE("1-"&AU$4)),IF(OR(COUNTA($A5:$F5)>0,$G5<>""),$N5/12*IF($F5="",1,MAX(0,(EOMONTH(_xlpm.m,0)-MAX($F5,_xlpm.m)+1)/(EOMONTH(_xlpm.m,0)-_xlpm.m+1))),"")) | AV5: =_xlfn.LET(_xlpm.m,IF(ISNUMBER(AV$4),DATE(YEAR(AV$4),MONTH(AV$4),1),DATEVALUE("1-"&AV$4)),IF(OR(COUNTA($A5:$F5)>0,$G5<>""),$N5/12*IF($F5="",1,MAX(0,(EOMONTH(_xlpm.m,0)-MAX($F5,_xlpm.m)+1)/(EOMONTH(_xlpm.m,0)-_xlpm.m+1))),"")) | ... AZ5: =_xlfn.LET(_xlpm.m,IF(ISNUMBER(AZ$4),DATE(YEAR(AZ$4),MONTH(AZ$4),1),DATEVALUE("1-"&AZ$4)),IF(OR(COUNTA($A5:$F5)>0,$G5<>""),$N5/12*IF($F5="",1,MAX(0,(EOMONTH(_xlpm.m,0)-MAX($F5,_xlpm.m)+1)/(EOMONTH(_xlpm.m,0)-_xlpm.m+1))),"")) | BA5: =IF(OR(COUNTA($A5:$F5)>0,$G5<>""),SUM(AO5:AZ5),"")
I6: =IF(OR(COUNTA(tblPayrollIncrementalSpend2[[#This Row],[Job Title]:[Hire Date]])>0,AND(ROW()=ROW(G6),tblPayrollIncrementalSpend2[[#This Row],[Base Salary]]<>"")),N(tblPayrollIncrementalSpend2[[#This Row],[Base Salary]])*N(tblPayrollIncrementalSpend2[[#This Row],[Bonus %]]),"") | J6: =IF(OR(COUNTA(tblPayrollIncrementalSpend2[[#This Row],[Job Title]:[Hire Date]])>0,AND(ROW()=ROW(G6),tblPayrollIncrementalSpend2[[#This Row],[Base Salary]]<>"")),N(tblPayrollIncrementalSpend2[[#This Row],[Base Salary]])*'Base - Payroll'!$E$12,"") | K6: =IF(OR(COUNTA(tblPayrollIncrementalSpend2[[#This Row],[Job Title]:[Hire Date]])>0,AND(ROW()=ROW(G6),tblPayrollIncrementalSpend2[[#This Row],[Base Salary]]<>"")),N(tblPayrollIncrementalSpend2[[#This Row],[Base Salary]])*'Base - Payroll'!$E$13,"") | L6: =IF(OR(COUNTA(tblPayrollIncrementalSpend2[[#This Row],[Job Title]:[Hire Date]])>0,AND(ROW()=ROW(G6),tblPayrollIncrementalSpend2[[#This Row],[Base Salary]]<>"")),N(tblPayrollIncrementalSpend2[[#This Row],[Base Salary]])*'Base - Payroll'!$E$15,"") | M6: =IF(OR(COUNTA(tblPayrollIncrementalSpend2[[#This Row],[Job Title]:[Hire Date]])>0,AND(ROW()=ROW(G6),tblPayrollIncrementalSpend2[[#This Row],[Base Salary]]<>"")),N(tblPayrollIncrementalSpend2[[#This Row],[Base Salary]])*'Base - Payroll'!$E$16,"") | N6: =IF(OR(COUNTA(tblPayrollIncrementalSpend2[[#This Row],[Job Title]:[Hire Date]])>0,AND(ROW()=ROW(G6),tblPayrollIncrementalSpend2[[#This Row],[Base Salary]]<>"")),N(tblPayrollIncrementalSpend2[[#This Row],[Base Salary]])+SUM(tblPayrollIncrementalSpend2[[#This Row],[Bonus]:[Other]]),"") | O6: =_xlfn.LET(_xlpm.m,IF(ISNUMBER(O$4),DATE(YEAR(O$4),MONTH(O$4),1),DATEVALUE("1-"&O$4)),IF(OR(COUNTA($A6:$F6)>0,$G6<>""),$N6/12*IF($F6="",1,MAX(0,(EOMONTH(_xlpm.m,0)-MAX($F6,_xlpm.m)+1)/(EOMONTH(_xlpm.m,0)-_xlpm.m+1))),"")) | P6: =_xlfn.LET(_xlpm.m,IF(ISNUMBER(P$4),DATE(YEAR(P$4),MONTH(P$4),1),DATEVALUE("1-"&P$4)),IF(OR(COUNTA($A6:$F6)>0,$G6<>""),$N6/12*IF($F6="",1,MAX(0,(EOMONTH(_xlpm.m,0)-MAX($F6,_xlpm.m)+1)/(EOMONTH(_xlpm.m,0)-_xlpm.m+1))),"")) | Q6: =_xlfn.LET(_xlpm.m,IF(ISNUMBER(Q$4),DATE(YEAR(Q$4),MONTH(Q$4),1),DATEVALUE("1-"&Q$4)),IF(OR(COUNTA($A6:$F6)>0,$G6<>""),$N6/12*IF($F6="",1,MAX(0,(EOMONTH(_xlpm.m,0)-MAX($F6,_xlpm.m)+1)/(EOMONTH(_xlpm.m,0)-_xlpm.m+1))),"")) | R6: =_xlfn.LET(_xlpm.m,IF(ISNUMBER(R$4),DATE(YEAR(R$4),MONTH(R$4),1),DATEVALUE("1-"&R$4)),IF(OR(COUNTA($A6:$F6)>0,$G6<>""),$N6/12*IF($F6="",1,MAX(0,(EOMONTH(_xlpm.m,0)-MAX($F6,_xlpm.m)+1)/(EOMONTH(_xlpm.m,0)-_xlpm.m+1))),"")) | S6: =_xlfn.LET(_xlpm.m,IF(ISNUMBER(S$4),DATE(YEAR(S$4),MONTH(S$4),1),DATEVALUE("1-"&S$4)),IF(OR(COUNTA($A6:$F6)>0,$G6<>""),$N6/12*IF($F6="",1,MAX(0,(EOMONTH(_xlpm.m,0)-MAX($F6,_xlpm.m)+1)/(EOMONTH(_xlpm.m,0)-_xlpm.m+1))),"")) | T6: =_xlfn.LET(_xlpm.m,IF(ISNUMBER(T$4),DATE(YEAR(T$4),MONTH(T$4),1),DATEVALUE("1-"&T$4)),IF(OR(COUNTA($A6:$F6)>0,$G6<>""),$N6/12*IF($F6="",1,MAX(0,(EOMONTH(_xlpm.m,0)-MAX($F6,_xlpm.m)+1)/(EOMONTH(_xlpm.m,0)-_xlpm.m+1))),"")) | U6: =_xlfn.LET(_xlpm.m,IF(ISNUMBER(U$4),DATE(YEAR(U$4),MONTH(U$4),1),DATEVALUE("1-"&U$4)),IF(OR(COUNTA($A6:$F6)>0,$G6<>""),$N6/12*IF($F6="",1,MAX(0,(EOMONTH(_xlpm.m,0)-MAX($F6,_xlpm.m)+1)/(EOMONTH(_xlpm.m,0)-_xlpm.m+1))),"")) | V6: =_xlfn.LET(_xlpm.m,IF(ISNUMBER(V$4),DATE(YEAR(V$4),MONTH(V$4),1),DATEVALUE("1-"&V$4)),IF(OR(COUNTA($A6:$F6)>0,$G6<>""),$N6/12*IF($F6="",1,MAX(0,(EOMONTH(_xlpm.m,0)-MAX($F6,_xlpm.m)+1)/(EOMONTH(_xlpm.m,0)-_xlpm.m+1))),"")) | ... Z6: =_xlfn.LET(_xlpm.m,IF(ISNUMBER(Z$4),DATE(YEAR(Z$4),MONTH(Z$4),1),DATEVALUE("1-"&Z$4)),IF(OR(COUNTA($A6:$F6)>0,$G6<>""),$N6/12*IF($F6="",1,MAX(0,(EOMONTH(_xlpm.m,0)-MAX($F6,_xlpm.m)+1)/(EOMONTH(_xlpm.m,0)-_xlpm.m+1))),"")) | AA6: =IF(OR(COUNTA($A6:$F6)>0,$G6<>""),SUM(O6:Z6),"") | AB6: =_xlfn.LET(_xlpm.m,IF(ISNUMBER(AB$4),DATE(YEAR(AB$4),MONTH(AB$4),1),DATEVALUE("1-"&AB$4)),IF(OR(COUNTA($A6:$F6)>0,$G6<>""),$N6/12*IF($F6="",1,MAX(0,(EOMONTH(_xlpm.m,0)-MAX($F6,_xlpm.m)+1)/(EOMONTH(_xlpm.m,0)-_xlpm.m+1))),"")) | AC6: =_xlfn.LET(_xlpm.m,IF(ISNUMBER(AC$4),DATE(YEAR(AC$4),MONTH(AC$4),1),DATEVALUE("1-"&AC$4)),IF(OR(COUNTA($A6:$F6)>0,$G6<>""),$N6/12*IF($F6="",1,MAX(0,(EOMONTH(_xlpm.m,0)-MAX($F6,_xlpm.m)+1)/(EOMONTH(_xlpm.m,0)-_xlpm.m+1))),"")) | AD6: =_xlfn.LET(_xlpm.m,IF(ISNUMBER(AD$4),DATE(YEAR(AD$4),MONTH(AD$4),1),DATEVALUE("1-"&AD$4)),IF(OR(COUNTA($A6:$F6)>0,$G6<>""),$N6/12*IF($F6="",1,MAX(0,(EOMONTH(_xlpm.m,0)-MAX($F6,_xlpm.m)+1)/(EOMONTH(_xlpm.m,0)-_xlpm.m+1))),"")) | AE6: =_xlfn.LET(_xlpm.m,IF(ISNUMBER(AE$4),DATE(YEAR(AE$4),MONTH(AE$4),1),DATEVALUE("1-"&AE$4)),IF(OR(COUNTA($A6:$F6)>0,$G6<>""),$N6/12*IF($F6="",1,MAX(0,(EOMONTH(_xlpm.m,0)-MAX($F6,_xlpm.m)+1)/(EOMONTH(_xlpm.m,0)-_xlpm.m+1))),"")) | AF6: =_xlfn.LET(_xlpm.m,IF(ISNUMBER(AF$4),DATE(YEAR(AF$4),MONTH(AF$4),1),DATEVALUE("1-"&AF$4)),IF(OR(COUNTA($A6:$F6)>0,$G6<>""),$N6/12*IF($F6="",1,MAX(0,(EOMONTH(_xlpm.m,0)-MAX($F6,_xlpm.m)+1)/(EOMONTH(_xlpm.m,0)-_xlpm.m+1))),"")) | AG6: =_xlfn.LET(_xlpm.m,IF(ISNUMBER(AG$4),DATE(YEAR(AG$4),MONTH(AG$4),1),DATEVALUE("1-"&AG$4)),IF(OR(COUNTA($A6:$F6)>0,$G6<>""),$N6/12*IF($F6="",1,MAX(0,(EOMONTH(_xlpm.m,0)-MAX($F6,_xlpm.m)+1)/(EOMONTH(_xlpm.m,0)-_xlpm.m+1))),"")) | AH6: =_xlfn.LET(_xlpm.m,IF(ISNUMBER(AH$4),DATE(YEAR(AH$4),MONTH(AH$4),1),DATEVALUE("1-"&AH$4)),IF(OR(COUNTA($A6:$F6)>0,$G6<>""),$N6/12*IF($F6="",1,MAX(0,(EOMONTH(_xlpm.m,0)-MAX($F6,_xlpm.m)+1)/(EOMONTH(_xlpm.m,0)-_xlpm.m+1))),"")) | AI6: =_xlfn.LET(_xlpm.m,IF(ISNUMBER(AI$4),DATE(YEAR(AI$4),MONTH(AI$4),1),DATEVALUE("1-"&AI$4)),IF(OR(COUNTA($A6:$F6)>0,$G6<>""),$N6/12*IF($F6="",1,MAX(0,(EOMONTH(_xlpm.m,0)-MAX($F6,_xlpm.m)+1)/(EOMONTH(_xlpm.m,0)-_xlpm.m+1))),"")) | ... AM6: =_xlfn.LET(_xlpm.m,IF(ISNUMBER(AM$4),DATE(YEAR(AM$4),MONTH(AM$4),1),DATEVALUE("1-"&AM$4)),IF(OR(COUNTA($A6:$F6)>0,$G6<>""),$N6/12*IF($F6="",1,MAX(0,(EOMONTH(_xlpm.m,0)-MAX($F6,_xlpm.m)+1)/(EOMONTH(_xlpm.m,0)-_xlpm.m+1))),"")) | AN6: =IF(OR(COUNTA($A6:$F6)>0,$G6<>""),SUM(AB6:AM6),"") | AO6: =_xlfn.LET(_xlpm.m,IF(ISNUMBER(AO$4),DATE(YEAR(AO$4),MONTH(AO$4),1),DATEVALUE("1-"&AO$4)),IF(OR(COUNTA($A6:$F6)>0,$G6<>""),$N6/12*IF($F6="",1,MAX(0,(EOMONTH(_xlpm.m,0)-MAX($F6,_xlpm.m)+1)/(EOMONTH(_xlpm.m,0)-_xlpm.m+1))),"")) | AP6: =_xlfn.LET(_xlpm.m,IF(ISNUMBER(AP$4),DATE(YEAR(AP$4),MONTH(AP$4),1),DATEVALUE("1-"&AP$4)),IF(OR(COUNTA($A6:$F6)>0,$G6<>""),$N6/12*IF($F6="",1,MAX(0,(EOMONTH(_xlpm.m,0)-MAX($F6,_xlpm.m)+1)/(EOMONTH(_xlpm.m,0)-_xlpm.m+1))),"")) | AQ6: =_xlfn.LET(_xlpm.m,IF(ISNUMBER(AQ$4),DATE(YEAR(AQ$4),MONTH(AQ$4),1),DATEVALUE("1-"&AQ$4)),IF(OR(COUNTA($A6:$F6)>0,$G6<>""),$N6/12*IF($F6="",1,MAX(0,(EOMONTH(_xlpm.m,0)-MAX($F6,_xlpm.m)+1)/(EOMONTH(_xlpm.m,0)-_xlpm.m+1))),"")) | AR6: =_xlfn.LET(_xlpm.m,IF(ISNUMBER(AR$4),DATE(YEAR(AR$4),MONTH(AR$4),1),DATEVALUE("1-"&AR$4)),IF(OR(COUNTA($A6:$F6)>0,$G6<>""),$N6/12*IF($F6="",1,MAX(0,(EOMONTH(_xlpm.m,0)-MAX($F6,_xlpm.m)+1)/(EOMONTH(_xlpm.m,0)-_xlpm.m+1))),"")) | AS6: =_xlfn.LET(_xlpm.m,IF(ISNUMBER(AS$4),DATE(YEAR(AS$4),MONTH(AS$4),1),DATEVALUE("1-"&AS$4)),IF(OR(COUNTA($A6:$F6)>0,$G6<>""),$N6/12*IF($F6="",1,MAX(0,(EOMONTH(_xlpm.m,0)-MAX($F6,_xlpm.m)+1)/(EOMONTH(_xlpm.m,0)-_xlpm.m+1))),"")) | AT6: =_xlfn.LET(_xlpm.m,IF(ISNUMBER(AT$4),DATE(YEAR(AT$4),MONTH(AT$4),1),DATEVALUE("1-"&AT$4)),IF(OR(COUNTA($A6:$F6)>0,$G6<>""),$N6/12*IF($F6="",1,MAX(0,(EOMONTH(_xlpm.m,0)-MAX($F6,_xlpm.m)+1)/(EOMONTH(_xlpm.m,0)-_xlpm.m+1))),"")) | AU6: =_xlfn.LET(_xlpm.m,IF(ISNUMBER(AU$4),DATE(YEAR(AU$4),MONTH(AU$4),1),DATEVALUE("1-"&AU$4)),IF(OR(COUNTA($A6:$F6)>0,$G6<>""),$N6/12*IF($F6="",1,MAX(0,(EOMONTH(_xlpm.m,0)-MAX($F6,_xlpm.m)+1)/(EOMONTH(_xlpm.m,0)-_xlpm.m+1))),"")) | AV6: =_xlfn.LET(_xlpm.m,IF(ISNUMBER(AV$4),DATE(YEAR(AV$4),MONTH(AV$4),1),DATEVALUE("1-"&AV$4)),IF(OR(COUNTA($A6:$F6)>0,$G6<>""),$N6/12*IF($F6="",1,MAX(0,(EOMONTH(_xlpm.m,0)-MAX($F6,_xlpm.m)+1)/(EOMONTH(_xlpm.m,0)-_xlpm.m+1))),"")) | ... AZ6: =_xlfn.LET(_xlpm.m,IF(ISNUMBER(AZ$4),DATE(YEAR(AZ$4),MONTH(AZ$4),1),DATEVALUE("1-"&AZ$4)),IF(OR(COUNTA($A6:$F6)>0,$G6<>""),$N6/12*IF($F6="",1,MAX(0,(EOMONTH(_xlpm.m,0)-MAX($F6,_xlpm.m)+1)/(EOMONTH(_xlpm.m,0)-_xlpm.m+1))),"")) | BA6: =IF(OR(COUNTA($A6:$F6)>0,$G6<>""),SUM(AO6:AZ6),"")
